Workbook

Sheet digestion_page
A1: Date: | B1: 46216
A2: Request ID: | B2: 100048725
A5: Microwave
A6: Analyte(s) | B6: Ca, Cr, Cu, Fe, K, Na, Ni, Zn
A7: SOP#
A8: Acid Cocktail | B8: 9 mL HCl, 3 mL HNO3, 6 mL H2SO4
A9: Rack | B9: 7
A10: Vessel | B10: PTFE
A11: Stir | B11: 0.9
A12: Time (min) | B12: Power (W) | C12: T1 (°C) | D12: T2 (°C) | E12: P (bar)
A13: 15 | B13: 1200 | C13: 180 | D13: 65 | E13: 110
A14: 15 | B14: 1500 | C14: 240 | D14: 65 | E14: 110
A15: 30 | B15: 1500 | C15: 240 | D15: 65 | E15: 110
A16: sample(s) | B16: weight (g) | C16: volume (mL)
A17: 200128458_1 | B17: 1.2525 | C17: 50
A18: 200128458_2 | B18: 1.2525 | C18: 50
A19: 200128458_3 | B19: 1.2543 | C19: 50
A20: 200128459_1 | B20: 1.2555 | C20: 50
A21: 200128459_2 | B21: 1.255 | C21: 50
A22: 200128459_3 | B22: 1.2544 | C22: 50
A23: 200128460_1 | B23: 1.2531 | C23: 50
A24: 200128460_2 | B24: 1.2526 | C24: 50
A25: 200128460_3 | B25: 1.2577 | C25: 50
A26: 200128461_1 | B26: 1.2557 | C26: 50
A27: 200128461_2 | B27: 1.2545 | C27: 50
A28: 200128461_3 | B28: 1.2561 | C28: 50

Sheet 200128458
A1: Date: | B1: 46216
A2: Request ID: | B2: 100048725
A5: Ca ICP analysis
A6: sample | B6: Dilution | C6: conc. [mg/L] | D6: Ca_ppm | E6: %Ca
A7: 200128458_1 | B7: ="1/1" -> 1/1 | C7: =AVERAGE(3.664,3.387,3.605) -> 3.552 | D7: =((C7)*(H7)*(I7))/(G7*1) -> 141.79641 | E7: =D7/10000 -> 0.014179641 | G7: =digestion_page!B17 -> 1.2525 | H7: =digestion_page!C17 -> 50 | I7: =(LEFT(B7,FIND("/",B7)-1)/RIGHT(B7,LEN(B7)-FIND("/", B7))) -> 1
A8: 200128458_2 | B8: ="1/1" -> 1/1 | C8: =AVERAGE(3.621,3.377,3.595) -> 3.531 | D8: =((C8)*(H8)*(I8))/(G8*1) -> 140.95808 | E8: =D8/10000 -> 0.014095808 | G8: =digestion_page!B18 -> 1.2525 | H8: =digestion_page!C18 -> 50 | I8: =(LEFT(B8,FIND("/",B8)-1)/RIGHT(B8,LEN(B8)-FIND("/", B8))) -> 1
A9: 200128458_3 | B9: ="1/1" -> 1/1 | C9: =AVERAGE(3.566,3.321,3.543) -> 3.4766667 | D9: =((C9)*(H9)*(I9))/(G9*1) -> 138.58992 | E9: =D9/10000 -> 0.013858992 | G9: =digestion_page!B19 -> 1.2543 | H9: =digestion_page!C19 -> 50 | I9: =(LEFT(B9,FIND("/",B9)-1)/RIGHT(B9,LEN(B9)-FIND("/", B9))) -> 1
A11: ca result: | C11: =AVERAGE(D7:D9) -> 140.44814
A12: ca result: | C12: =AVERAGE(E7:E9) -> 0.014044814
A13: ca lot: | C13: Manufacturer: Assurance, 28-35CAY exp: 2026-10-30
A15: Cr ICP analysis
A16: sample | B16: Dilution | C16: conc. [mg/L] | D16: Cr_ppm | E16: %Cr
A17: 200128458_1 | B17: ="1/1" -> 1/1 | C17: =AVERAGE(1.578,1.492,1.554) -> 1.5413333 | D17: =((C17)*(H17)*(I17))/(G17*1) -> 61.530273 | E17: =D17/10000 -> 0.0061530273 | G17: =digestion_page!B17 -> 1.2525 | H17: =digestion_page!C17 -> 50 | I17: =(LEFT(B17,FIND("/",B17)-1)/RIGHT(B17,LEN(B17)-FIND("/", B17))) -> 1
A18: 200128458_2 | B18: ="1/1" -> 1/1 | C18: =AVERAGE(1.616,1.52,1.56) -> 1.5653333 | D18: =((C18)*(H18)*(I18))/(G18*1) -> 62.488357 | E18: =D18/10000 -> 0.0062488357 | G18: =digestion_page!B18 -> 1.2525 | H18: =digestion_page!C18 -> 50 | I18: =(LEFT(B18,FIND("/",B18)-1)/RIGHT(B18,LEN(B18)-FIND("/", B18))) -> 1
A19: 200128458_3 | B19: ="1/1" -> 1/1 | C19: =AVERAGE(1.61,1.509,1.553) -> 1.5573333 | D19: =((C19)*(H19)*(I19))/(G19*1) -> 62.079779 | E19: =D19/10000 -> 0.0062079779 | G19: =digestion_page!B19 -> 1.2543 | H19: =digestion_page!C19 -> 50 | I19: =(LEFT(B19,FIND("/",B19)-1)/RIGHT(B19,LEN(B19)-FIND("/", B19))) -> 1
A21: cr result: | C21: =AVERAGE(D17:D19) -> 62.032803
A22: cr result: | C22: =AVERAGE(E17:E19) -> 0.0062032803
A23: cr lot: | C23: Manufacturer: Ricca, 45120423 exp: 2027-05-31
A25: Cu ICP analysis
A26: sample | B26: Dilution | C26: conc. [mg/L] | D26: Cu_ppm | E26: %Cu
A27: 200128458_1 | B27: ="1/1" -> 1/1 | C27: 3.153 | D27: =((C27)*(H27)*(I27))/(G27*1) -> 125.86826 | E27: =D27/10000 -> 0.012586826 | G27: =digestion_page!B17 -> 1.2525 | H27: =digestion_page!C17 -> 50 | I27: =(LEFT(B27,FIND("/",B27)-1)/RIGHT(B27,LEN(B27)-FIND("/", B27))) -> 1
A28: 200128458_2 | B28: ="1/1" -> 1/1 | C28: 3.207 | D28: =((C28)*(H28)*(I28))/(G28*1) -> 128.02395 | E28: =D28/10000 -> 0.012802395 | G28: =digestion_page!B18 -> 1.2525 | H28: =digestion_page!C18 -> 50 | I28: =(LEFT(B28,FIND("/",B28)-1)/RIGHT(B28,LEN(B28)-FIND("/", B28))) -> 1
A29: 200128458_3 | B29: ="1/1" -> 1/1 | C29: 3.184 | D29: =((C29)*(H29)*(I29))/(G29*1) -> 126.92338 | E29: =D29/10000 -> 0.012692338 | G29: =digestion_page!B19 -> 1.2543 | H29: =digestion_page!C19 -> 50 | I29: =(LEFT(B29,FIND("/",B29)-1)/RIGHT(B29,LEN(B29)-FIND("/", B29))) -> 1
A31: cu result: | C31: =AVERAGE(D27:D29) -> 126.93853
A32: cu result: | C32: =AVERAGE(E27:E29) -> 0.012693853
A33: cu lot: | C33: Manufacturer: Assurance, 28-83CUT exp: 2026-09-30
A35: Fe ICP analysis
A36: sample | B36: Dilution | C36: conc. [mg/L] | D36: Fe_ppm | E36: %Fe
A37: 200128458_1 | B37: ="1/1" -> 1/1 | C37: =AVERAGE(2.047,2.216) -> 2.1315 | D37: =((C37)*(H37)*(I37))/(G37*1) -> 85.08982 | E37: =D37/10000 -> 0.008508982 | G37: =digestion_page!B17 -> 1.2525 | H37: =digestion_page!C17 -> 50 | I37: =(LEFT(B37,FIND("/",B37)-1)/RIGHT(B37,LEN(B37)-FIND("/", B37))) -> 1
A38: 200128458_2 | B38: ="1/1" -> 1/1 | C38: =AVERAGE(2.074,2.243) -> 2.1585 | D38: =((C38)*(H38)*(I38))/(G38*1) -> 86.167665 | E38: =D38/10000 -> 0.0086167665 | G38: =digestion_page!B18 -> 1.2525 | H38: =digestion_page!C18 -> 50 | I38: =(LEFT(B38,FIND("/",B38)-1)/RIGHT(B38,LEN(B38)-FIND("/", B38))) -> 1
A39: 200128458_3 | B39: ="1/1" -> 1/1 | C39: =AVERAGE(1.972,2.122) -> 2.047 | D39: =((C39)*(H39)*(I39))/(G39*1) -> 81.599298 | E39: =D39/10000 -> 0.0081599298 | G39: =digestion_page!B19 -> 1.2543 | H39: =digestion_page!C19 -> 50 | I39: =(LEFT(B39,FIND("/",B39)-1)/RIGHT(B39,LEN(B39)-FIND("/", B39))) -> 1
A41: fe result: | C41: =AVERAGE(D37:D39) -> 84.285594
A42: fe result: | C42: =AVERAGE(E37:E39) -> 0.0084285594
A43: fe lot: | C43: Manufacturer: Assurance, 28-180FEY exp: 2027-07-30
A45: K ICP analysis
A46: sample | B46: Dilution | C46: conc. [mg/L] | D46: K_ppm | E46: %K
A47: 200128458_1 | B47: ="10/1" -> 10/1 | C47: =AVERAGE(0.357,0.355) -> 0.356 | D47: =((C47)*(H47)*(I47))/(G47*1) -> 142.11577 | E47: =D47/10000 -> 0.014211577 | G47: =digestion_page!B17 -> 1.2525 | H47: =digestion_page!C17 -> 50 | I47: =(LEFT(B47,FIND("/",B47)-1)/RIGHT(B47,LEN(B47)-FIND("/", B47))) -> 10
A48: 200128458_2 | B48: ="10/1" -> 10/1 | C48: =AVERAGE(0.342,0.339) -> 0.3405 | D48: =((C48)*(H48)*(I48))/(G48*1) -> 135.92814 | E48: =D48/10000 -> 0.013592814 | G48: =digestion_page!B18 -> 1.2525 | H48: =digestion_page!C18 -> 50 | I48: =(LEFT(B48,FIND("/",B48)-1)/RIGHT(B48,LEN(B48)-FIND("/", B48))) -> 10
A49: 200128458_3 | B49: ="10/1" -> 10/1 | C49: =AVERAGE(0.321,0.321) -> 0.321 | D49: =((C49)*(H49)*(I49))/(G49*1) -> 127.95982 | E49: =D49/10000 -> 0.012795982 | G49: =digestion_page!B19 -> 1.2543 | H49: =digestion_page!C19 -> 50 | I49: =(LEFT(B49,FIND("/",B49)-1)/RIGHT(B49,LEN(B49)-FIND("/", B49))) -> 10
A51: k result: | C51: =AVERAGE(D47:D49) -> 135.33458
...

Sheet 200128459
A1: Date: | B1: 46216
A2: Request ID: | B2: 100048725
A5: Ca ICP analysis
A6: sample | B6: Dilution | C6: conc. [mg/L] | D6: Ca_ppm | E6: %Ca
A7: 200128459_1 | B7: ="1/1" -> 1/1 | C7: =AVERAGE(3.295,3.169,3.367) -> 3.277 | D7: =((C7)*(H7)*(I7))/(G7*1) -> 130.50577 | E7: =D7/10000 -> 0.013050577 | G7: =digestion_page!B20 -> 1.2555 | H7: =digestion_page!C20 -> 50 | I7: =(LEFT(B7,FIND("/",B7)-1)/RIGHT(B7,LEN(B7)-FIND("/", B7))) -> 1
A8: 200128459_2 | B8: ="1/1" -> 1/1 | C8: =AVERAGE(3.192,3.083,3.29) -> 3.1883333 | D8: =((C8)*(H8)*(I8))/(G8*1) -> 127.02523 | E8: =D8/10000 -> 0.012702523 | G8: =digestion_page!B21 -> 1.255 | H8: =digestion_page!C21 -> 50 | I8: =(LEFT(B8,FIND("/",B8)-1)/RIGHT(B8,LEN(B8)-FIND("/", B8))) -> 1
A9: 200128459_3 | B9: ="1/1" -> 1/1 | C9: =AVERAGE(3.322,3.208,3.415) -> 3.315 | D9: =((C9)*(H9)*(I9))/(G9*1) -> 132.13489 | E9: =D9/10000 -> 0.013213489 | G9: =digestion_page!B22 -> 1.2544 | H9: =digestion_page!C22 -> 50 | I9: =(LEFT(B9,FIND("/",B9)-1)/RIGHT(B9,LEN(B9)-FIND("/", B9))) -> 1
A11: ca result: | C11: =AVERAGE(D7:D9) -> 129.88863
A12: ca result: | C12: =AVERAGE(E7:E9) -> 0.012988863
A13: ca lot: | C13: Manufacturer: Assurance, 28-35CAY exp: 2026-10-30
A15: Cr ICP analysis
A16: sample | B16: Dilution | C16: conc. [mg/L] | D16: Cr_ppm | E16: %Cr
A17: 200128459_1 | B17: ="1/1" -> 1/1 | C17: =AVERAGE(1.629,1.521,1.549) -> 1.5663333 | D17: =((C17)*(H17)*(I17))/(G17*1) -> 62.378866 | E17: =D17/10000 -> 0.0062378866 | G17: =digestion_page!B20 -> 1.2555 | H17: =digestion_page!C20 -> 50 | I17: =(LEFT(B17,FIND("/",B17)-1)/RIGHT(B17,LEN(B17)-FIND("/", B17))) -> 1
A18: 200128459_2 | B18: ="1/1" -> 1/1 | C18: =AVERAGE(1.573,1.46,1.496) -> 1.5096667 | D18: =((C18)*(H18)*(I18))/(G18*1) -> 60.146082 | E18: =D18/10000 -> 0.0060146082 | G18: =digestion_page!B21 -> 1.255 | H18: =digestion_page!C21 -> 50 | I18: =(LEFT(B18,FIND("/",B18)-1)/RIGHT(B18,LEN(B18)-FIND("/", B18))) -> 1
A19: 200128459_3 | B19: ="1/1" -> 1/1 | C19: =AVERAGE(1.652,1.524,1.539) -> 1.5716667 | D19: =((C19)*(H19)*(I19))/(G19*1) -> 62.646152 | E19: =D19/10000 -> 0.0062646152 | G19: =digestion_page!B22 -> 1.2544 | H19: =digestion_page!C22 -> 50 | I19: =(LEFT(B19,FIND("/",B19)-1)/RIGHT(B19,LEN(B19)-FIND("/", B19))) -> 1
A21: cr result: | C21: =AVERAGE(D17:D19) -> 61.7237
A22: cr result: | C22: =AVERAGE(E17:E19) -> 0.00617237
A23: cr lot: | C23: Manufacturer: Ricca, 45120423 exp: 2027-05-31
A25: Cu ICP analysis
A26: sample | B26: Dilution | C26: conc. [mg/L] | D26: Cu_ppm | E26: %Cu
A27: 200128459_1 | B27: ="1/1" -> 1/1 | C27: 3.985 | D27: =((C27)*(H27)*(I27))/(G27*1) -> 158.70171 | E27: =D27/10000 -> 0.015870171 | G27: =digestion_page!B20 -> 1.2555 | H27: =digestion_page!C20 -> 50 | I27: =(LEFT(B27,FIND("/",B27)-1)/RIGHT(B27,LEN(B27)-FIND("/", B27))) -> 1
A28: 200128459_2 | B28: ="1/1" -> 1/1 | C28: 4.063 | D28: =((C28)*(H28)*(I28))/(G28*1) -> 161.87251 | E28: =D28/10000 -> 0.016187251 | G28: =digestion_page!B21 -> 1.255 | H28: =digestion_page!C21 -> 50 | I28: =(LEFT(B28,FIND("/",B28)-1)/RIGHT(B28,LEN(B28)-FIND("/", B28))) -> 1
A29: 200128459_3 | B29: ="1/1" -> 1/1 | C29: 4.054 | D29: =((C29)*(H29)*(I29))/(G29*1) -> 161.5912 | E29: =D29/10000 -> 0.01615912 | G29: =digestion_page!B22 -> 1.2544 | H29: =digestion_page!C22 -> 50 | I29: =(LEFT(B29,FIND("/",B29)-1)/RIGHT(B29,LEN(B29)-FIND("/", B29))) -> 1
A31: cu result: | C31: =AVERAGE(D27:D29) -> 160.72181
A32: cu result: | C32: =AVERAGE(E27:E29) -> 0.016072181
A33: cu lot: | C33: Manufacturer: Assurance, 28-83CUT exp: 2026-09-30
A35: Fe ICP analysis
A36: sample | B36: Dilution | C36: conc. [mg/L] | D36: Fe_ppm | E36: %Fe
A37: 200128459_1 | B37: ="1/1" -> 1/1 | C37: =AVERAGE(1.695,1.947) -> 1.821 | D37: =((C37)*(H37)*(I37))/(G37*1) -> 72.520908 | E37: =D37/10000 -> 0.0072520908 | G37: =digestion_page!B20 -> 1.2555 | H37: =digestion_page!C20 -> 50 | I37: =(LEFT(B37,FIND("/",B37)-1)/RIGHT(B37,LEN(B37)-FIND("/", B37))) -> 1
A38: 200128459_2 | B38: ="1/1" -> 1/1 | C38: =AVERAGE(1.584,1.835) -> 1.7095 | D38: =((C38)*(H38)*(I38))/(G38*1) -> 68.10757 | E38: =D38/10000 -> 0.006810757 | G38: =digestion_page!B21 -> 1.255 | H38: =digestion_page!C21 -> 50 | I38: =(LEFT(B38,FIND("/",B38)-1)/RIGHT(B38,LEN(B38)-FIND("/", B38))) -> 1
A39: 200128459_3 | B39: ="1/1" -> 1/1 | C39: =AVERAGE(1.646,1.9) -> 1.773 | D39: =((C39)*(H39)*(I39))/(G39*1) -> 70.671237 | E39: =D39/10000 -> 0.0070671237 | G39: =digestion_page!B22 -> 1.2544 | H39: =digestion_page!C22 -> 50 | I39: =(LEFT(B39,FIND("/",B39)-1)/RIGHT(B39,LEN(B39)-FIND("/", B39))) -> 1
A41: fe result: | C41: =AVERAGE(D37:D39) -> 70.433238
A42: fe result: | C42: =AVERAGE(E37:E39) -> 0.0070433238
A43: fe lot: | C43: Manufacturer: Assurance, 28-180FEY exp: 2027-07-30
A45: K ICP analysis
A46: sample | B46: Dilution | C46: conc. [mg/L] | D46: K_ppm | E46: %K
A47: 200128459_1 | B47: ="10/1" -> 10/1 | C47: =AVERAGE(0.361,0.363) -> 0.362 | D47: =((C47)*(H47)*(I47))/(G47*1) -> 144.16567 | E47: =D47/10000 -> 0.014416567 | G47: =digestion_page!B20 -> 1.2555 | H47: =digestion_page!C20 -> 50 | I47: =(LEFT(B47,FIND("/",B47)-1)/RIGHT(B47,LEN(B47)-FIND("/", B47))) -> 10
A48: 200128459_2 | B48: ="10/1" -> 10/1 | C48: =AVERAGE(0.31,0.314) -> 0.312 | D48: =((C48)*(H48)*(I48))/(G48*1) -> 124.30279 | E48: =D48/10000 -> 0.012430279 | G48: =digestion_page!B21 -> 1.255 | H48: =digestion_page!C21 -> 50 | I48: =(LEFT(B48,FIND("/",B48)-1)/RIGHT(B48,LEN(B48)-FIND("/", B48))) -> 10
A49: 200128459_3 | B49: ="10/1" -> 10/1 | C49: =AVERAGE(0.355,0.359) -> 0.357 | D49: =((C49)*(H49)*(I49))/(G49*1) -> 142.29911 | E49: =D49/10000 -> 0.014229911 | G49: =digestion_page!B22 -> 1.2544 | H49: =digestion_page!C22 -> 50 | I49: =(LEFT(B49,FIND("/",B49)-1)/RIGHT(B49,LEN(B49)-FIND("/", B49))) -> 10
A51: k result: | C51: =AVERAGE(D47:D49) -> 136.92252
...

Sheet 200128460
A1: Date: | B1: 46216
A2: Request ID: | B2: 100048725
A5: Ca ICP analysis
A6: sample | B6: Dilution | C6: conc. [mg/L] | D6: Ca_ppm | E6: %Ca
A7: 200128460_1 | B7: ="10/2" -> 10/2 | C7: =AVERAGE(2.74,2.811) -> 2.7755 | D7: =((C7)*(H7)*(I7))/(G7*1) -> 553.72676 | E7: =D7/10000 -> 0.055372676 | G7: =digestion_page!B23 -> 1.2531 | H7: =digestion_page!C23 -> 50 | I7: =(LEFT(B7,FIND("/",B7)-1)/RIGHT(B7,LEN(B7)-FIND("/", B7))) -> 5
A8: 200128460_2 | B8: ="10/2" -> 10/2 | C8: =AVERAGE(2.788,2.89) -> 2.839 | D8: =((C8)*(H8)*(I8))/(G8*1) -> 566.62143 | E8: =D8/10000 -> 0.056662143 | G8: =digestion_page!B24 -> 1.2526 | H8: =digestion_page!C24 -> 50 | I8: =(LEFT(B8,FIND("/",B8)-1)/RIGHT(B8,LEN(B8)-FIND("/", B8))) -> 5
A9: 200128460_3 | B9: ="10/2" -> 10/2 | C9: =AVERAGE(2.62,2.755) -> 2.6875 | D9: =((C9)*(H9)*(I9))/(G9*1) -> 534.20927 | E9: =D9/10000 -> 0.053420927 | G9: =digestion_page!B25 -> 1.2577 | H9: =digestion_page!C25 -> 50 | I9: =(LEFT(B9,FIND("/",B9)-1)/RIGHT(B9,LEN(B9)-FIND("/", B9))) -> 5
A11: ca result: | C11: =AVERAGE(D7:D9) -> 551.51915
A12: ca result: | C12: =AVERAGE(E7:E9) -> 0.055151915
A13: ca lot: | C13: Manufacturer: Assurance, 28-35CAY exp: 2026-10-30
A15: Cr ICP analysis
A16: sample | B16: Dilution | C16: conc. [mg/L] | D16: Cr_ppm | E16: %Cr
A17: 200128460_1 | B17: ="10/2" -> 10/2 | C17: =AVERAGE(2.402) -> 2.402 | D17: =((C17)*(H17)*(I17))/(G17*1) -> 479.21156 | E17: =D17/10000 -> 0.047921156 | G17: =digestion_page!B23 -> 1.2531 | H17: =digestion_page!C23 -> 50 | I17: =(LEFT(B17,FIND("/",B17)-1)/RIGHT(B17,LEN(B17)-FIND("/", B17))) -> 5
A18: 200128460_2 | B18: ="10/2" -> 10/2 | C18: =AVERAGE(2.085) -> 2.085 | D18: =((C18)*(H18)*(I18))/(G18*1) -> 416.13444 | E18: =D18/10000 -> 0.041613444 | G18: =digestion_page!B24 -> 1.2526 | H18: =digestion_page!C24 -> 50 | I18: =(LEFT(B18,FIND("/",B18)-1)/RIGHT(B18,LEN(B18)-FIND("/", B18))) -> 5
A19: 200128460_3 | B19: ="10/2" -> 10/2 | C19: =AVERAGE(2.145) -> 2.145 | D19: =((C19)*(H19)*(I19))/(G19*1) -> 426.37354 | E19: =D19/10000 -> 0.042637354 | G19: =digestion_page!B25 -> 1.2577 | H19: =digestion_page!C25 -> 50 | I19: =(LEFT(B19,FIND("/",B19)-1)/RIGHT(B19,LEN(B19)-FIND("/", B19))) -> 5
A21: cr result: | C21: =AVERAGE(D17:D19) -> 440.57318
A22: cr result: | C22: =AVERAGE(E17:E19) -> 0.044057318
A23: cr lot: | C23: Manufacturer: Ricca, 45120423 exp: 2027-05-31
A25: Cu ICP analysis
A26: sample | B26: Dilution | C26: conc. [mg/L] | D26: Cu_ppm | E26: %Cu
A27: 200128460_1 | B27: ="10/2" -> 10/2 | C27: =AVERAGE(2.705,2.609,2.805) -> 2.7063333 | D27: =((C27)*(H27)*(I27))/(G27*1) -> 539.92765 | E27: =D27/10000 -> 0.053992765 | G27: =digestion_page!B23 -> 1.2531 | H27: =digestion_page!C23 -> 50 | I27: =(LEFT(B27,FIND("/",B27)-1)/RIGHT(B27,LEN(B27)-FIND("/", B27))) -> 5
A28: 200128460_2 | B28: ="10/2" -> 10/2 | C28: =AVERAGE(2.704,2.566,2.729) -> 2.6663333 | D28: =((C28)*(H28)*(I28))/(G28*1) -> 532.15977 | E28: =D28/10000 -> 0.053215977 | G28: =digestion_page!B24 -> 1.2526 | H28: =digestion_page!C24 -> 50 | I28: =(LEFT(B28,FIND("/",B28)-1)/RIGHT(B28,LEN(B28)-FIND("/", B28))) -> 5
A29: 200128460_3 | B29: ="10/2" -> 10/2 | C29: =AVERAGE(2.708,2.534,2.615) -> 2.619 | D29: =((C29)*(H29)*(I29))/(G29*1) -> 520.59315 | E29: =D29/10000 -> 0.052059315 | G29: =digestion_page!B25 -> 1.2577 | H29: =digestion_page!C25 -> 50 | I29: =(LEFT(B29,FIND("/",B29)-1)/RIGHT(B29,LEN(B29)-FIND("/", B29))) -> 5
A31: cu result: | C31: =AVERAGE(D27:D29) -> 530.89352
A32: cu result: | C32: =AVERAGE(E27:E29) -> 0.053089352
A33: cu lot: | C33: Manufacturer: Assurance, 28-83CUT exp: 2026-09-30
A35: Fe ICP analysis
A36: sample | B36: Dilution | C36: conc. [mg/L] | D36: Fe_ppm | E36: %Fe
A37: 200128460_1 | B37: ="10/2" -> 10/2 | C37: =AVERAGE(2.505) -> 2.505 | D37: =((C37)*(H37)*(I37))/(G37*1) -> 499.76059 | E37: =D37/10000 -> 0.049976059 | G37: =digestion_page!B23 -> 1.2531 | H37: =digestion_page!C23 -> 50 | I37: =(LEFT(B37,FIND("/",B37)-1)/RIGHT(B37,LEN(B37)-FIND("/", B37))) -> 5
A38: 200128460_2 | B38: ="10/2" -> 10/2 | C38: 2.782 | D38: =((C38)*(H38)*(I38))/(G38*1) -> 555.24509 | E38: =D38/10000 -> 0.055524509 | G38: =digestion_page!B24 -> 1.2526 | H38: =digestion_page!C24 -> 50 | I38: =(LEFT(B38,FIND("/",B38)-1)/RIGHT(B38,LEN(B38)-FIND("/", B38))) -> 5
A39: 200128460_3 | B39: ="10/2" -> 10/2 | C39: 2.756 | D39: =((C39)*(H39)*(I39))/(G39*1) -> 547.8254 | E39: =D39/10000 -> 0.05478254 | G39: =digestion_page!B25 -> 1.2577 | H39: =digestion_page!C25 -> 50 | I39: =(LEFT(B39,FIND("/",B39)-1)/RIGHT(B39,LEN(B39)-FIND("/", B39))) -> 5
A41: fe result: | C41: =AVERAGE(D37:D39) -> 534.27703
A42: fe result: | C42: =AVERAGE(E37:E39) -> 0.053427703
A43: fe lot: | C43: Manufacturer: Assurance, 28-180FEY exp: 2027-07-30
A45: K ICP analysis
A46: sample | B46: Dilution | C46: conc. [mg/L] | D46: K_ppm | E46: %K
A47: 200128460_1 | B47: ="25/1" -> 25/1 | C47: 0.957 | D47: =((C47)*(H47)*(I47))/(G47*1) -> 954.63251 | E47: =D47/10000 -> 0.095463251 | G47: =digestion_page!B23 -> 1.2531 | H47: =digestion_page!C23 -> 50 | I47: =(LEFT(B47,FIND("/",B47)-1)/RIGHT(B47,LEN(B47)-FIND("/", B47))) -> 25
A48: 200128460_2 | B48: ="25/1" -> 25/1 | C48: 0.929 | D48: =((C48)*(H48)*(I48))/(G48*1) -> 927.07169 | E48: =D48/10000 -> 0.092707169 | G48: =digestion_page!B24 -> 1.2526 | H48: =digestion_page!C24 -> 50 | I48: =(LEFT(B48,FIND("/",B48)-1)/RIGHT(B48,LEN(B48)-FIND("/", B48))) -> 25
A49: 200128460_3 | B49: ="25/1" -> 25/1 | C49: 0.919 | D49: =((C49)*(H49)*(I49))/(G49*1) -> 913.37362 | E49: =D49/10000 -> 0.091337362 | G49: =digestion_page!B25 -> 1.2577 | H49: =digestion_page!C25 -> 50 | I49: =(LEFT(B49,FIND("/",B49)-1)/RIGHT(B49,LEN(B49)-FIND("/", B49))) -> 25
A51: k result: | C51: =AVERAGE(D47:D49) -> 931.69261
...

Sheet 200128461
A1: Date: | B1: 46216
A2: Request ID: | B2: 100048725
A5: Ca ICP analysis
A6: sample | B6: Dilution | C6: conc. [mg/L] | D6: Ca_ppm | E6: %Ca
A7: 200128461_1 | B7: ="10/2" -> 10/2 | C7: =AVERAGE(2.597) -> 2.597 | D7: =((C7)*(H7)*(I7))/(G7*1) -> 517.04229 | E7: =D7/10000 -> 0.051704229 | G7: =digestion_page!B26 -> 1.2557 | H7: =digestion_page!C26 -> 50 | I7: =(LEFT(B7,FIND("/",B7)-1)/RIGHT(B7,LEN(B7)-FIND("/", B7))) -> 5
A8: 200128461_2 | B8: ="10/2" -> 10/2 | C8: =2.611 -> 2.611 | D8: =((C8)*(H8)*(I8))/(G8*1) -> 520.32682 | E8: =D8/10000 -> 0.052032682 | G8: =digestion_page!B27 -> 1.2545 | H8: =digestion_page!C27 -> 50 | I8: =(LEFT(B8,FIND("/",B8)-1)/RIGHT(B8,LEN(B8)-FIND("/", B8))) -> 5
A9: 200128461_3 | B9: ="10/2" -> 10/2 | C9: 2.875 | D9: =((C9)*(H9)*(I9))/(G9*1) -> 572.20763 | E9: =D9/10000 -> 0.057220763 | G9: =digestion_page!B28 -> 1.2561 | H9: =digestion_page!C28 -> 50 | I9: =(LEFT(B9,FIND("/",B9)-1)/RIGHT(B9,LEN(B9)-FIND("/", B9))) -> 5
A11: ca result: | C11: =AVERAGE(D7:D9) -> 536.52558
A12: ca result: | C12: =AVERAGE(E7:E9) -> 0.053652558
A13: ca lot: | C13: Manufacturer: Assurance, 28-35CAY exp: 2026-10-30
A15: Cr ICP analysis
A16: sample | B16: Dilution | C16: conc. [mg/L] | D16: Cr_ppm | E16: %Cr
A17: 200128461_1 | B17: ="10/2" -> 10/2 | C17: 2.222 | D17: =((C17)*(H17)*(I17))/(G17*1) -> 442.38273 | E17: =D17/10000 -> 0.044238273 | G17: =digestion_page!B26 -> 1.2557 | H17: =digestion_page!C26 -> 50 | I17: =(LEFT(B17,FIND("/",B17)-1)/RIGHT(B17,LEN(B17)-FIND("/", B17))) -> 5
A18: 200128461_2 | B18: ="10/2" -> 10/2 | C18: 2.447 | D18: =((C18)*(H18)*(I18))/(G18*1) -> 487.64448 | E18: =D18/10000 -> 0.048764448 | G18: =digestion_page!B27 -> 1.2545 | H18: =digestion_page!C27 -> 50 | I18: =(LEFT(B18,FIND("/",B18)-1)/RIGHT(B18,LEN(B18)-FIND("/", B18))) -> 5
A19: 200128461_3 | B19: ="10/2" -> 10/2 | C19: 2.157 | D19: =((C19)*(H19)*(I19))/(G19*1) -> 429.30499 | E19: =D19/10000 -> 0.042930499 | G19: =digestion_page!B28 -> 1.2561 | H19: =digestion_page!C28 -> 50 | I19: =(LEFT(B19,FIND("/",B19)-1)/RIGHT(B19,LEN(B19)-FIND("/", B19))) -> 5
A21: cr result: | C21: =AVERAGE(D17:D19) -> 453.11074
A22: cr result: | C22: =AVERAGE(E17:E19) -> 0.045311074
A23: cr lot: | C23: Manufacturer: Ricca, 45120423 exp: 2027-05-31
A25: Cu ICP analysis
A26: sample | B26: Dilution | C26: conc. [mg/L] | D26: Cu_ppm | E26: %Cu
A27: 200128461_1 | B27: ="10/2" -> 10/2 | C27: =AVERAGE(2.53,2.484,2.845) -> 2.6196667 | D27: =((C27)*(H27)*(I27))/(G27*1) -> 521.55504 | E27: =D27/10000 -> 0.052155504 | G27: =digestion_page!B26 -> 1.2557 | H27: =digestion_page!C26 -> 50 | I27: =(LEFT(B27,FIND("/",B27)-1)/RIGHT(B27,LEN(B27)-FIND("/", B27))) -> 5
A28: 200128461_2 | B28: ="10/2" -> 10/2 | C28: =AVERAGE(2.747,2.683,2.967) -> 2.799 | D28: =((C28)*(H28)*(I28))/(G28*1) -> 557.79195 | E28: =D28/10000 -> 0.055779195 | G28: =digestion_page!B27 -> 1.2545 | H28: =digestion_page!C27 -> 50 | I28: =(LEFT(B28,FIND("/",B28)-1)/RIGHT(B28,LEN(B28)-FIND("/", B28))) -> 5
A29: 200128461_3 | B29: ="10/2" -> 10/2 | C29: =AVERAGE(2.534,2.48,2.735) -> 2.583 | D29: =((C29)*(H29)*(I29))/(G29*1) -> 514.09123 | E29: =D29/10000 -> 0.051409123 | G29: =digestion_page!B28 -> 1.2561 | H29: =digestion_page!C28 -> 50 | I29: =(LEFT(B29,FIND("/",B29)-1)/RIGHT(B29,LEN(B29)-FIND("/", B29))) -> 5
A31: cu result: | C31: =AVERAGE(D27:D29) -> 531.14608
A32: cu result: | C32: =AVERAGE(E27:E29) -> 0.053114608
A33: cu lot: | C33: Manufacturer: Assurance, 28-83CUT exp: 2026-09-30
A35: Fe ICP analysis
A36: sample | B36: Dilution | C36: conc. [mg/L] | D36: Fe_ppm | E36: %Fe
A37: 200128461_2 | B37: ="10/2" -> 10/2 | C37: 2.926 | D37: =((C37)*(H37)*(I37))/(G37*1) -> 583.10084 | E37: =D37/10000 -> 0.058310084 | G37: =digestion_page!B27 -> 1.2545 | H37: =digestion_page!C27 -> 50 | I37: =(LEFT(B37,FIND("/",B37)-1)/RIGHT(B37,LEN(B37)-FIND("/", B37))) -> 5
A38: 200128461_3 | B38: ="10/2" -> 10/2 | C38: 2.47 | D38: =((C38)*(H38)*(I38))/(G38*1) -> 491.60099 | E38: =D38/10000 -> 0.049160099 | G38: =digestion_page!B28 -> 1.2561 | H38: =digestion_page!C28 -> 50 | I38: =(LEFT(B38,FIND("/",B38)-1)/RIGHT(B38,LEN(B38)-FIND("/", B38))) -> 5
A40: fe result: | C40: =AVERAGE(D37:D38) -> 537.35091
A41: fe result: | C41: =AVERAGE(E37:E38) -> 0.053735091
A42: fe lot: | C42: Manufacturer: Assurance, 28-180FEY exp: 2027-07-30
A44: K ICP analysis
A45: sample | B45: Dilution | C45: conc. [mg/L] | D45: K_ppm | E45: %K
A46: 200128461_1 | B46: ="25/1" -> 25/1 | C46: 0.887 | D46: =((C46)*(H46)*(I46))/(G46*1) -> 882.97364 | E46: =D46/10000 -> 0.088297364 | G46: =digestion_page!B26 -> 1.2557 | H46: =digestion_page!C26 -> 50 | I46: =(LEFT(B46,FIND("/",B46)-1)/RIGHT(B46,LEN(B46)-FIND("/", B46))) -> 25
A47: 200128461_2 | B47: ="25/1" -> 25/1 | C47: 0.91 | D47: =((C47)*(H47)*(I47))/(G47*1) -> 906.73575 | E47: =D47/10000 -> 0.090673575 | G47: =digestion_page!B27 -> 1.2545 | H47: =digestion_page!C27 -> 50 | I47: =(LEFT(B47,FIND("/",B47)-1)/RIGHT(B47,LEN(B47)-FIND("/", B47))) -> 25
A48: 200128461_3 | B48: ="25/1" -> 25/1 | C48: 0.908 | D48: =((C48)*(H48)*(I48))/(G48*1) -> 903.59048 | E48: =D48/10000 -> 0.090359048 | G48: =digestion_page!B28 -> 1.2561 | H48: =digestion_page!C28 -> 50 | I48: =(LEFT(B48,FIND("/",B48)-1)/RIGHT(B48,LEN(B48)-FIND("/", B48))) -> 25
A50: k result: | C50: =AVERAGE(D46:D48) -> 897.76662
A51: k result: | C51: =AVERAGE(E46:E48) -> 0.089776662
...

Sheet formula_page
A1: ppm M+ = [conc.][volume][dilution]/[weight]
A3: %M+ = [conc.][volume][dilution]/([weight]*10,000)
A5: %MO = [oxide factor]*%M+
