Workbook

Sheet digestion_page
A1: Date: | B1: 46233
A2: Request ID: | B2: 100048830
A5: Katanax
A6: Analyte(s) | B6: Cr, Cu, Mg, Si, Ti
A7: SOP#
A8: Acid Cocktail | B8: 30 mL conc. HCl
A9: sample(s) | B9: weight (g) | C9: volume (mL)
A10: 200128736_1 | B10: 0.3097 | C10: 250
A11: 200128736_2 | B11: 0.3059 | C11: 250
A12: 200128737_1 | B12: 0.3057 | C12: 250
A13: 200128737_2 | B13: 0.3023 | C13: 250
A16: Hotplate
A17: Analyte(s) | B17: Na
A18: SOP#
A19: Cocktail | B19: 50 mL 1:1 HCl
A20: sample(s) | B20: weight (g) | C20: volume (mL)
A21: 200128736_1 | B21: 0.5062 | C21: 50
A22: 200128736_2 | B22: 0.5043 | C22: 50
A23: 200128737_1 | B23: 0.5092 | C23: 50
A24: 200128737_2 | B24: 0.5053 | C24: 50

Sheet 200128736
A1: Date: | B1: 46233
A2: Request ID: | B2: 100048830
A5: LOI temp: | B5: 900
A6: sample | B6: crucible (g) | C6: crucible + sample (g) | D6: ="after "&B5&" °C" -> after 900 °C | E6: LOI (%) | F6: correction
A7: 200128736 | B7: 16.603 | C7: 18.6492 | D7: 18.5184 | E7: =(((C7-B7)-(D7-B7))/(C7-B7))*100 -> 6.392337 | F7: =1-(E7/100) -> 0.93607663
A9: Cr ICP analysis
A10: sample | B10: Dilution | C10: conc. [mg/L] | D10: Cr_ppm [dried] | E10: %Cr [dried]
A11: 200128736_1 | B11: ="25/1" -> 25/1 | C11: =AVERAGE(2.411,2.339,2.37) -> 2.3733333 | D11: =((C11)*(H11)*(I11))/(G11*$F$7) -> 51166.552 | E11: =D11/10000 -> 5.1166552 | G11: =digestion_page!B10 -> 0.3097 | H11: =digestion_page!C10 -> 250 | I11: =(LEFT(B11,FIND("/",B11)-1)/RIGHT(B11,LEN(B11)-FIND("/", B11))) -> 25
A12: 200128736_2 | B12: ="25/1" -> 25/1 | C12: =AVERAGE(2.298,2.301,2.367) -> 2.322 | D12: =((C12)*(H12)*(I12))/(G12*$F$7) -> 50681.721 | E12: =D12/10000 -> 5.0681721 | G12: =digestion_page!B11 -> 0.3059 | H12: =digestion_page!C11 -> 250 | I12: =(LEFT(B12,FIND("/",B12)-1)/RIGHT(B12,LEN(B12)-FIND("/", B12))) -> 25
A14: cr result: | C14: =AVERAGE(D11:D12) -> 50924.136
A15: cr result: | C15: =AVERAGE(E11:E12) -> 5.0924136
A16: cr oxide factor: | C16: 1.462
A17: cr oxide result: | C17: =AVERAGE(E11:E12)*(C16) -> 7.4451087
A18: cr lot: | C18: Manufacturer: Ricca, 45120423 exp: 2027-05-31
A20: Cu ICP analysis
A21: sample | B21: Dilution | C21: conc. [mg/L] | D21: Cu_ppm [dried] | E21: %Cu [dried]
A22: 200128736_1 | B22: ="50/6" -> 50/6 | C22: =AVERAGE(1.912,1.855,1.89,1.888) -> 1.88625 | D22: =((C22)*(H22)*(I22))/(G22*$F$7) -> 13555.184 | E22: =D22/10000 -> 1.3555184 | G22: =digestion_page!B10 -> 0.3097 | H22: =digestion_page!C10 -> 250 | I22: =(LEFT(B22,FIND("/",B22)-1)/RIGHT(B22,LEN(B22)-FIND("/", B22))) -> 8.3333333
A23: 200128736_2 | B23: ="50/6" -> 50/6 | C23: =AVERAGE(1.882,1.836,1.853,1.854) -> 1.85625 | D23: =((C23)*(H23)*(I23))/(G23*$F$7) -> 13505.304 | E23: =D23/10000 -> 1.3505304 | G23: =digestion_page!B11 -> 0.3059 | H23: =digestion_page!C11 -> 250 | I23: =(LEFT(B23,FIND("/",B23)-1)/RIGHT(B23,LEN(B23)-FIND("/", B23))) -> 8.3333333
A25: cu result: | C25: =AVERAGE(D22:D23) -> 13530.244
A26: cu result: | C26: =AVERAGE(E22:E23) -> 1.3530244
A27: cu oxide factor: | C27: 1.252
A28: cu oxide result: | C28: =AVERAGE(E22:E23)*(C27) -> 1.6939865
A29: cu lot: | C29: Manufacturer: Assurance, 28-83CUT exp: 2026-09-30
A31: Mg ICP analysis
A32: sample | B32: Dilution | C32: conc. [mg/L] | D32: Mg_ppm [dried] | E32: %Mg [dried]
A33: 200128736_1 | B33: ="10/9" -> 10/9 | C33: =AVERAGE(0.216,0.214,0.214) -> 0.21466667 | D33: =((C33)*(H33)*(I33))/(G33*$F$7) -> 205.68826 | E33: =D33/10000 -> 0.020568826 | G33: =digestion_page!B10 -> 0.3097 | H33: =digestion_page!C10 -> 250 | I33: =(LEFT(B33,FIND("/",B33)-1)/RIGHT(B33,LEN(B33)-FIND("/", B33))) -> 1.1111111
A34: 200128736_2 | B34: ="10/9" -> 10/9 | C34: =AVERAGE(0.216,0.214,0.214) -> 0.21466667 | D34: =((C34)*(H34)*(I34))/(G34*$F$7) -> 208.24339 | E34: =D34/10000 -> 0.020824339 | G34: =digestion_page!B11 -> 0.3059 | H34: =digestion_page!C11 -> 250 | I34: =(LEFT(B34,FIND("/",B34)-1)/RIGHT(B34,LEN(B34)-FIND("/", B34))) -> 1.1111111
A36: mg result: | C36: =AVERAGE(D33:D34) -> 206.96583
A37: mg result: | C37: =AVERAGE(E33:E34) -> 0.020696583
A38: mg lot: | C38: Manufacturer: Assurance, 28-136MGY exp: 2027-01-30
A40: Na ICP analysis
A41: sample | B41: Dilution | C41: conc. [mg/L] | D41: Na_ppm [dried] | E41: %Na [dried]
A42: 200128736_1 | B42: ="25/1" -> 25/1 | C42: =AVERAGE(0.851,0.877) -> 0.864 | D42: =((C42)*(H42)*(I42))/(G42*$F$7) -> 2279.2408 | E42: =D42/10000 -> 0.22792408 | G42: =digestion_page!B21 -> 0.5062 | H42: =digestion_page!C21 -> 50 | I42: =(LEFT(B42,FIND("/",B42)-1)/RIGHT(B42,LEN(B42)-FIND("/", B42))) -> 25
A43: 200128736_2 | B43: ="25/1" -> 25/1 | C43: =AVERAGE(0.875,0.879) -> 0.877 | D43: =((C43)*(H43)*(I43))/(G43*$F$7) -> 2322.2514 | E43: =D43/10000 -> 0.23222514 | G43: =digestion_page!B22 -> 0.5043 | H43: =digestion_page!C22 -> 50 | I43: =(LEFT(B43,FIND("/",B43)-1)/RIGHT(B43,LEN(B43)-FIND("/", B43))) -> 25
A45: na result: | C45: =AVERAGE(D42:D43) -> 2300.7461
A46: na result: | C46: =AVERAGE(E42:E43) -> 0.23007461
A47: na lot: | C47: Manufacturer: Assurance, 27-159NAY exp: 2026-08-30
A49: Si ICP analysis
A50: sample | B50: Dilution | C50: conc. [mg/L] | D50: Si_ppm [dried] | E50: %Si [dried]
A51: 200128736_1 | B51: ="250/250" -> 250/250 | C51: =AVERAGE(1.093,1.097) -> 1.095 | D51: =((C51)*(H51)*(I51))/(G51*$F$7) -> 944.28158 | E51: =D51/10000 -> 0.094428158 | G51: =digestion_page!B10 -> 0.3097 | H51: =digestion_page!C10 -> 250 | I51: =(LEFT(B51,FIND("/",B51)-1)/RIGHT(B51,LEN(B51)-FIND("/", B51))) -> 1
...

Sheet 200128737
A1: Date: | B1: 46233
A2: Request ID: | B2: 100048830
A5: LOI temp: | B5: 900
A6: sample | B6: crucible (g) | C6: crucible + sample (g) | D6: ="after "&B5&" °C" -> after 900 °C | E6: LOI (%) | F6: correction
A7: 200128737 | B7: 18.6915 | C7: 20.8111 | D7: 20.7101 | E7: =(((C7-B7)-(D7-B7))/(C7-B7))*100 -> 4.76505 | F7: =1-(E7/100) -> 0.9523495
A9: Cr ICP analysis
A10: sample | B10: Dilution | C10: conc. [mg/L] | D10: Cr_ppm [dried] | E10: %Cr [dried]
A11: 200128737_1 | B11: ="25/0.77" -> 25/0.77 | C11: =AVERAGE(2.1,2.104,2.112) -> 2.1053333 | D11: =((C11)*(H11)*(I11))/(G11*$F$7) -> 58697.332 | E11: =D11/10000 -> 5.8697332 | G11: =digestion_page!B12 -> 0.3057 | H11: =digestion_page!C12 -> 250 | I11: =(LEFT(B11,FIND("/",B11)-1)/RIGHT(B11,LEN(B11)-FIND("/", B11))) -> 32.467532
A12: 200128737_2 | B12: ="25/0.77" -> 25/0.77 | C12: =AVERAGE(2.169,2.122,2.15) -> 2.147 | D12: =((C12)*(H12)*(I12))/(G12*$F$7) -> 60532.252 | E12: =D12/10000 -> 6.0532252 | G12: =digestion_page!B13 -> 0.3023 | H12: =digestion_page!C13 -> 250 | I12: =(LEFT(B12,FIND("/",B12)-1)/RIGHT(B12,LEN(B12)-FIND("/", B12))) -> 32.467532
A14: cr result: | C14: =AVERAGE(D11:D12) -> 59614.792
A15: cr result: | C15: =AVERAGE(E11:E12) -> 5.9614792
A16: cr oxide factor: | C16: 1.462
A17: cr oxide result: | C17: =AVERAGE(E11:E12)*(C16) -> 8.7156826
A18: cr lot: | C18: Manufacturer: Ricca, 45120423 exp: 2027-05-31
A20: Cu ICP analysis
A21: sample | B21: Dilution | C21: conc. [mg/L] | D21: Cu_ppm [dried] | E21: %Cu [dried]
A22: 200128737_1 | B22: ="10/1" -> 10/1 | C22: =AVERAGE(1.642,1.569,1.607,1.604) -> 1.6055 | D22: =((C22)*(H22)*(I22))/(G22*$F$7) -> 13786.643 | E22: =D22/10000 -> 1.3786643 | G22: =digestion_page!B12 -> 0.3057 | H22: =digestion_page!C12 -> 250 | I22: =(LEFT(B22,FIND("/",B22)-1)/RIGHT(B22,LEN(B22)-FIND("/", B22))) -> 10
A23: 200128737_2 | B23: ="10/1" -> 10/1 | C23: =AVERAGE(1.758,1.712,1.721,1.726) -> 1.72925 | D23: =((C23)*(H23)*(I23))/(G23*$F$7) -> 15016.312 | E23: =D23/10000 -> 1.5016312 | G23: =digestion_page!B13 -> 0.3023 | H23: =digestion_page!C13 -> 250 | I23: =(LEFT(B23,FIND("/",B23)-1)/RIGHT(B23,LEN(B23)-FIND("/", B23))) -> 10
A25: cu result: | C25: =AVERAGE(D22:D23) -> 14401.477
A26: cu result: | C26: =AVERAGE(E22:E23) -> 1.4401477
A27: cu oxide factor: | C27: 1.252
A28: cu oxide result: | C28: =AVERAGE(E22:E23)*(C27) -> 1.803065
A29: cu lot: | C29: Manufacturer: Assurance, 28-83CUT exp: 2026-09-30
A31: Mg ICP analysis
A32: sample | B32: Dilution | C32: conc. [mg/L] | D32: Mg_ppm [dried] | E32: %Mg [dried]
A33: 200128737_1 | B33: ="10/9" -> 10/9 | C33: =AVERAGE(0.125,0.123) -> 0.124 | D33: =((C33)*(H33)*(I33))/(G33*$F$7) -> 118.31162 | E33: =D33/10000 -> 0.011831162 | G33: =digestion_page!B12 -> 0.3057 | H33: =digestion_page!C12 -> 250 | I33: =(LEFT(B33,FIND("/",B33)-1)/RIGHT(B33,LEN(B33)-FIND("/", B33))) -> 1.1111111
A34: 200128737_2 | B34: ="10/9" -> 10/9 | C34: =AVERAGE(0.126,0.124) -> 0.125 | D34: =((C34)*(H34)*(I34))/(G34*$F$7) -> 120.60714 | E34: =D34/10000 -> 0.012060714 | G34: =digestion_page!B13 -> 0.3023 | H34: =digestion_page!C13 -> 250 | I34: =(LEFT(B34,FIND("/",B34)-1)/RIGHT(B34,LEN(B34)-FIND("/", B34))) -> 1.1111111
A36: mg result: | C36: =AVERAGE(D33:D34) -> 119.45938
A37: mg result: | C37: =AVERAGE(E33:E34) -> 0.011945938
A38: mg lot: | C38: Manufacturer: Assurance, 28-136MGY exp: 2027-01-30
A40: Na ICP analysis
A41: sample | B41: Dilution | C41: conc. [mg/L] | D41: Na_ppm [dried] | E41: %Na [dried]
A42: 200128737_1 | B42: ="25/1" -> 25/1 | C42: =AVERAGE(0.81,0.809) -> 0.8095 | D42: =((C42)*(H42)*(I42))/(G42*$F$7) -> 2086.614 | E42: =D42/10000 -> 0.2086614 | G42: =digestion_page!B23 -> 0.5092 | H42: =digestion_page!C23 -> 50 | I42: =(LEFT(B42,FIND("/",B42)-1)/RIGHT(B42,LEN(B42)-FIND("/", B42))) -> 25
A43: 200128737_2 | B43: ="25/1" -> 25/1 | C43: =AVERAGE(0.812,0.811) -> 0.8115 | D43: =((C43)*(H43)*(I43))/(G43*$F$7) -> 2107.914 | E43: =D43/10000 -> 0.2107914 | G43: =digestion_page!B24 -> 0.5053 | H43: =digestion_page!C24 -> 50 | I43: =(LEFT(B43,FIND("/",B43)-1)/RIGHT(B43,LEN(B43)-FIND("/", B43))) -> 25
A45: na result: | C45: =AVERAGE(D42:D43) -> 2097.264
A46: na result: | C46: =AVERAGE(E42:E43) -> 0.2097264
A47: na lot: | C47: Manufacturer: Assurance, 27-159NAY exp: 2026-08-30
A49: Si ICP analysis
A50: sample | B50: Dilution | C50: conc. [mg/L] | D50: Si_ppm [dried] | E50: %Si [dried]
A51: 200128737_1 | B51: ="1/1" -> 1/1 | C51: =AVERAGE(1.65,1.663) -> 1.6565 | D51: =((C51)*(H51)*(I51))/(G51*$F$7) -> 1422.4587 | E51: =D51/10000 -> 0.14224587 | G51: =digestion_page!B12 -> 0.3057 | H51: =digestion_page!C12 -> 250 | I51: =(LEFT(B51,FIND("/",B51)-1)/RIGHT(B51,LEN(B51)-FIND("/", B51))) -> 1
...

Sheet formula_page
A1: ppm M+ = [conc.][volume][dilution]/[weight]
A3: %M+ = [conc.][volume][dilution]/([weight]*10,000)
A5: %MO = [oxide factor]*%M+
A7: A = crucible
A8: B = crucible + sample
A9: C = crucible + sample after drying
A11: %LOI = ([B-A]-[C-A])/(B-A)*100%
A13: ppm M+ [dried] = ppm M+/([1-(%LOI)/100])
A15: %M+ [dried] = %M+/([1-(%LOI)/100])
A17: %MO [dried] = %MO/([1-(%LOI)/100])
