Workbook

Sheet digestion_page
A1: Date: | B1: 46225
A2: Request ID: | B2: Wax Analysis
A5: Microwave
A6: Analyte(s) | B6: Al, Co, Cu, Ti
A7: SOP#
A8: Acid Cocktail
A9: Rack
A10: Vessel
A11: Stir
A12: Time (min) | B12: Power (W) | C12: T1 (°C) | D12: T2 (°C) | E12: P (bar)
A13: 15 | B13: 1200 | C13: 180 | D13: 65 | E13: 110
A14: 15 | B14: 1500 | C14: 240 | D14: 65 | E14: 110
A16: sample(s) | B16: weight (g) | C16: volume (mL)
A17: 200128352_1 | B17: 0.4561 | C17: 50
A18: 200128352_2 | B18: 0.4611 | C18: 50
A21: Microwave
A22: Analyte(s) | B22: Al_2, Co_2, Cu_2, Ti_2
A23: SOP#
A24: Acid Cocktail
A25: Rack
A26: Vessel
A27: Stir
A28: Time (min) | B28: Power (W) | C28: T1 (°C) | D28: T2 (°C) | E28: P (bar)
A29: 15 | B29: 1200 | C29: 180 | D29: 65 | E29: 110
A30: 15 | B30: 1500 | C30: 240 | D30: 65 | E30: 110
A32: sample(s) | B32: weight (g) | C32: volume (mL)
A33: 200128352_3 | B33: 0.1525 | C33: 25
A34: 200128352_4 | B34: 0.1697 | C34: 25
A37: Microwave
A38: Analyte(s) | B38: Al_3, Co_3, Cu_3, Ti_3
A39: SOP#
A40: Acid Cocktail
A41: Rack
A42: Vessel
A43: Stir
A44: Time (min) | B44: Power (W) | C44: T1 (°C) | D44: T2 (°C) | E44: P (bar)
A45: 15 | B45: 1200 | C45: 180 | D45: 65 | E45: 110
A46: 15 | B46: 1500 | C46: 240 | D46: 65 | E46: 110
A48: sample(s) | B48: weight (g) | C48: volume (mL)
A49: 200128352_5 | B49: 0.4002 | C49: 25
...

Sheet 200128352
A1: Date: | B1: 46225
A2: Request ID: | B2: Wax Analysis
A5: Al ICP analysis
A6: sample | B6: Dilution | C6: conc. [mg/L] | D6: Al_ppm | E6: %Al
A7: 200128352_1 | B7: ="1/1" -> 1/1 | C7: =AVERAGE(0.187,0.2,0.187,0.193) -> 0.19175 | D7: =((C7)*(H7)*(I7))/(G7*1) -> 21.02061 | E7: =D7/10000 -> 0.002102061 | G7: =digestion_page!B17 -> 0.4561 | H7: =digestion_page!C17 -> 50 | I7: =(LEFT(B7,FIND("/",B7)-1)/RIGHT(B7,LEN(B7)-FIND("/", B7))) -> 1
A8: 200128352_2 | B8: ="1/1" -> 1/1 | C8: =AVERAGE(0.185,0.189,0.178,0.193) -> 0.18625 | D8: =((C8)*(H8)*(I8))/(G8*1) -> 20.19627 | E8: =D8/10000 -> 0.002019627 | G8: =digestion_page!B18 -> 0.4611 | H8: =digestion_page!C18 -> 50 | I8: =(LEFT(B8,FIND("/",B8)-1)/RIGHT(B8,LEN(B8)-FIND("/", B8))) -> 1
A10: al result: | C10: =AVERAGE(D7:D8) -> 20.60844
A11: al result: | C11: =AVERAGE(E7:E8) -> 0.002060844
A12: al lot: | C12: Manufacturer: Assurance, 27-171ALT exp: 2026-07-30
A14: Co ICP analysis
A15: sample | B15: Dilution | C15: conc. [mg/L] | D15: Co_ppm | E15: %Co
A16: 200128352_1 | B16: ="1/1" -> 1/1 | C16: 0.029 | D16: =((C16)*(H16)*(I16))/(G16*1) -> 3.1791274 | E16: =D16/10000 -> 0.00031791274 | G16: =digestion_page!B17 -> 0.4561 | H16: =digestion_page!C17 -> 50 | I16: =(LEFT(B16,FIND("/",B16)-1)/RIGHT(B16,LEN(B16)-FIND("/", B16))) -> 1
A17: 200128352_2 | B17: ="1/1" -> 1/1 | C17: 0.027 | D17: =((C17)*(H17)*(I17))/(G17*1) -> 2.9277814 | E17: =D17/10000 -> 0.00029277814 | G17: =digestion_page!B18 -> 0.4611 | H17: =digestion_page!C18 -> 50 | I17: =(LEFT(B17,FIND("/",B17)-1)/RIGHT(B17,LEN(B17)-FIND("/", B17))) -> 1
A19: co result: | C19: =AVERAGE(D16:D17) -> 3.0534544
A20: co result: | C20: =AVERAGE(E16:E17) -> 0.00030534544
A21: co lot: | C21: Manufacturer: Assurance, 29-22COY exp: 2027-06-30
A23: Cu ICP analysis
A24: sample | B24: Dilution | C24: conc. [mg/L] | D24: Cu_ppm | E24: %Cu
A25: 200128352_1 | B25: ="1/1" -> 1/1 | C25: 0.003 | D25: =((C25)*(H25)*(I25))/(G25*1) -> 0.32887525 | E25: =D25/10000 -> 3.2887525e-05 | G25: =digestion_page!B17 -> 0.4561 | H25: =digestion_page!C17 -> 50 | I25: =(LEFT(B25,FIND("/",B25)-1)/RIGHT(B25,LEN(B25)-FIND("/", B25))) -> 1
A26: 200128352_2 | B26: ="1/1" -> 1/1 | C26: 0.003 | D26: =((C26)*(H26)*(I26))/(G26*1) -> 0.32530904 | E26: =D26/10000 -> 3.2530904e-05 | G26: =digestion_page!B18 -> 0.4611 | H26: =digestion_page!C18 -> 50 | I26: =(LEFT(B26,FIND("/",B26)-1)/RIGHT(B26,LEN(B26)-FIND("/", B26))) -> 1
A28: cu result: | C28: =AVERAGE(D25:D26) -> 0.32709215
A29: cu result: | C29: =AVERAGE(E25:E26) -> 3.2709215e-05
A30: cu lot: | C30: Manufacturer: Assurance, 28-83CUT exp: 2026-09-30
A32: Ti ICP analysis
A33: sample | B33: Dilution | C33: conc. [mg/L] | D33: Ti_ppm | E33: %Ti
A34: 200128352_1 | B34: ="1/1" -> 1/1 | C34: 0.035 | D34: =((C34)*(H34)*(I34))/(G34*1) -> 3.8368779 | E34: =D34/10000 -> 0.00038368779 | G34: =digestion_page!B17 -> 0.4561 | H34: =digestion_page!C17 -> 50 | I34: =(LEFT(B34,FIND("/",B34)-1)/RIGHT(B34,LEN(B34)-FIND("/", B34))) -> 1
A35: 200128352_2 | B35: ="1/1" -> 1/1 | C35: 0.032 | D35: =((C35)*(H35)*(I35))/(G35*1) -> 3.4699631 | E35: =D35/10000 -> 0.00034699631 | G35: =digestion_page!B18 -> 0.4611 | H35: =digestion_page!C18 -> 50 | I35: =(LEFT(B35,FIND("/",B35)-1)/RIGHT(B35,LEN(B35)-FIND("/", B35))) -> 1
A37: ti result: | C37: =AVERAGE(D34:D35) -> 3.6534205
A38: ti result: | C38: =AVERAGE(E34:E35) -> 0.00036534205
A39: ti lot: | C39: Manufacturer: Assurance, 27-189TIT exp: 2026-08-30
B41: Note(s):

Sheet 200128353
A1: Date: | B1: 46225
A2: Request ID: | B2: Wax Analysis
A5: Al_2 ICP analysis
A6: sample | B6: Dilution | C6: conc. [mg/L] | D6: Al_2_ppm | E6: %Al_2
A7: 200128353_1 | B7: ="1/1" -> 1/1 | C7: =AVERAGE(0.129,0.139,0.128,0.132) -> 0.132 | D7: =((C7)*(H7)*(I7))/(G7*1) -> 21.639344 | E7: =D7/10000 -> 0.0021639344 | G7: =digestion_page!B33 -> 0.1525 | H7: =digestion_page!C33 -> 25 | I7: =(LEFT(B7,FIND("/",B7)-1)/RIGHT(B7,LEN(B7)-FIND("/", B7))) -> 1
A8: 200128353_2 | B8: ="1/1" -> 1/1 | C8: =AVERAGE(0.492,0.495,0.48,0.489) -> 0.489 | D8: =((C8)*(H8)*(I8))/(G8*1) -> 72.038892 | E8: =D8/10000 -> 0.0072038892 | G8: =digestion_page!B34 -> 0.1697 | H8: =digestion_page!C34 -> 25 | I8: =(LEFT(B8,FIND("/",B8)-1)/RIGHT(B8,LEN(B8)-FIND("/", B8))) -> 1
A10: al_2 result: | C10: =AVERAGE(D7:D8) -> 46.839118
A11: al_2 result: | C11: =AVERAGE(E7:E8) -> 0.0046839118
A12: al_2 lot:
A14: Co_2 ICP analysis
A15: sample | B15: Dilution | C15: conc. [mg/L] | D15: Co_2_ppm | E15: %Co_2
A16: 200128353_1 | B16: ="1/1" -> 1/1 | C16: =AVERAGE(0.017,0.019,0.018,0.018) -> 0.018 | D16: =((C16)*(H16)*(I16))/(G16*1) -> 2.9508197 | E16: =D16/10000 -> 0.00029508197 | G16: =digestion_page!B33 -> 0.1525 | H16: =digestion_page!C33 -> 25 | I16: =(LEFT(B16,FIND("/",B16)-1)/RIGHT(B16,LEN(B16)-FIND("/", B16))) -> 1
A17: 200128353_2 | B17: ="1/1" -> 1/1 | C17: =AVERAGE(0.015,0.017,0.016,0.018) -> 0.0165 | D17: =((C17)*(H17)*(I17))/(G17*1) -> 2.4307602 | E17: =D17/10000 -> 0.00024307602 | G17: =digestion_page!B34 -> 0.1697 | H17: =digestion_page!C34 -> 25 | I17: =(LEFT(B17,FIND("/",B17)-1)/RIGHT(B17,LEN(B17)-FIND("/", B17))) -> 1
A19: co_2 result: | C19: =AVERAGE(D16:D17) -> 2.6907899
A20: co_2 result: | C20: =AVERAGE(E16:E17) -> 0.00026907899
A21: co_2 lot:
A23: Cu_2 ICP analysis
A24: sample | B24: Dilution | C24: conc. [mg/L] | D24: Cu_2_ppm | E24: %Cu_2
A25: 200128353_1 | B25: ="1/1" -> 1/1 | C25: 0.005 | D25: =((C25)*(H25)*(I25))/(G25*1) -> 0.81967213 | E25: =D25/10000 -> 8.1967213e-05 | G25: =digestion_page!B33 -> 0.1525 | H25: =digestion_page!C33 -> 25 | I25: =(LEFT(B25,FIND("/",B25)-1)/RIGHT(B25,LEN(B25)-FIND("/", B25))) -> 1
A26: 200128353_2 | B26: ="1/1" -> 1/1 | C26: 0.005 | D26: =((C26)*(H26)*(I26))/(G26*1) -> 0.73659399 | E26: =D26/10000 -> 7.3659399e-05 | G26: =digestion_page!B34 -> 0.1697 | H26: =digestion_page!C34 -> 25 | I26: =(LEFT(B26,FIND("/",B26)-1)/RIGHT(B26,LEN(B26)-FIND("/", B26))) -> 1
A28: cu_2 result: | C28: =AVERAGE(D25:D26) -> 0.77813306
A29: cu_2 result: | C29: =AVERAGE(E25:E26) -> 7.7813306e-05
A30: cu_2 lot:
A32: Ti_2 ICP analysis
A33: sample | B33: Dilution | C33: conc. [mg/L] | D33: Ti_2_ppm | E33: %Ti_2
A34: 200128353_1 | B34: ="1/1" -> 1/1 | C34: =AVERAGE(0.011,0.01,0.011,0.012) -> 0.011 | D34: =((C34)*(H34)*(I34))/(G34*1) -> 1.8032787 | E34: =D34/10000 -> 0.00018032787 | G34: =digestion_page!B33 -> 0.1525 | H34: =digestion_page!C33 -> 25 | I34: =(LEFT(B34,FIND("/",B34)-1)/RIGHT(B34,LEN(B34)-FIND("/", B34))) -> 1
A35: 200128353_2 | B35: ="1/1" -> 1/1 | C35: =AVERAGE(0.013,0.012,0.013,0.013) -> 0.01275 | D35: =((C35)*(H35)*(I35))/(G35*1) -> 1.8783147 | E35: =D35/10000 -> 0.00018783147 | G35: =digestion_page!B34 -> 0.1697 | H35: =digestion_page!C34 -> 25 | I35: =(LEFT(B35,FIND("/",B35)-1)/RIGHT(B35,LEN(B35)-FIND("/", B35))) -> 1
A37: ti_2 result: | C37: =AVERAGE(D34:D35) -> 1.8407967
A38: ti_2 result: | C38: =AVERAGE(E34:E35) -> 0.00018407967
A39: ti_2 lot:
B41: Note(s):

Sheet 200128354
A1: Date: | B1: 46225
A2: Request ID: | B2: Wax Analysis
A5: Al_3 ICP analysis
A6: sample | B6: Dilution | C6: conc. [mg/L] | D6: Al_3_ppm | E6: %Al_3
A7: 200128354_1 | B7: ="1/1" -> 1/1 | C7: =AVERAGE(1.991,1.967,1.907,1.926) -> 1.94775 | D7: =((C7)*(H7)*(I7))/(G7*1) -> 121.67354 | E7: =D7/10000 -> 0.012167354 | G7: =digestion_page!B49 -> 0.4002 | H7: =digestion_page!C49 -> 25 | I7: =(LEFT(B7,FIND("/",B7)-1)/RIGHT(B7,LEN(B7)-FIND("/", B7))) -> 1
A8: 200128354_2 | B8: ="1/1" -> 1/1 | C8: =AVERAGE(0.518,0.514,0.496,0.509) -> 0.50925 | D8: =((C8)*(H8)*(I8))/(G8*1) -> 31.693428 | E8: =D8/10000 -> 0.0031693428 | G8: =digestion_page!B50 -> 0.4017 | H8: =digestion_page!C50 -> 25 | I8: =(LEFT(B8,FIND("/",B8)-1)/RIGHT(B8,LEN(B8)-FIND("/", B8))) -> 1
A10: al_3 result: | C10: =AVERAGE(D7:D8) -> 76.683483
A11: al_3 result: | C11: =AVERAGE(E7:E8) -> 0.0076683483
A12: al_3 lot:
A14: Co_3 ICP analysis
A15: sample | B15: Dilution | C15: conc. [mg/L] | D15: Co_3_ppm | E15: %Co_3
A16: 200128354_1 | B16: ="1/1" -> 1/1 | C16: =AVERAGE(1.013,1.013,1.027,1.043) -> 1.024 | D16: =((C16)*(H16)*(I16))/(G16*1) -> 63.968016 | E16: =D16/10000 -> 0.0063968016 | G16: =digestion_page!B49 -> 0.4002 | H16: =digestion_page!C49 -> 25 | I16: =(LEFT(B16,FIND("/",B16)-1)/RIGHT(B16,LEN(B16)-FIND("/", B16))) -> 1
A17: 200128354_2 | B17: ="1/1" -> 1/1 | C17: =AVERAGE(0.151,0.154,0.154,0.159) -> 0.1545 | D17: =((C17)*(H17)*(I17))/(G17*1) -> 9.6153846 | E17: =D17/10000 -> 0.00096153846 | G17: =digestion_page!B50 -> 0.4017 | H17: =digestion_page!C50 -> 25 | I17: =(LEFT(B17,FIND("/",B17)-1)/RIGHT(B17,LEN(B17)-FIND("/", B17))) -> 1
A19: co_3 result: | C19: =AVERAGE(D16:D17) -> 36.7917
A20: co_3 result: | C20: =AVERAGE(E16:E17) -> 0.00367917
A21: co_3 lot:
A23: Cu_3 ICP analysis
A24: sample | B24: Dilution | C24: conc. [mg/L] | D24: Cu_3_ppm | E24: %Cu_3
A25: 200128354_1 | B25: ="1/1" -> 1/1 | C25: =AVERAGE(0,0.004,0.002) -> 0.002 | D25: =((C25)*(H25)*(I25))/(G25*1) -> 0.12493753 | E25: =D25/10000 -> 1.2493753e-05 | G25: =digestion_page!B49 -> 0.4002 | H25: =digestion_page!C49 -> 25 | I25: =(LEFT(B25,FIND("/",B25)-1)/RIGHT(B25,LEN(B25)-FIND("/", B25))) -> 1
A26: 200128354_2 | B26: ="1/1" -> 1/1 | C26: =AVERAGE(0,0.004,0.001) -> 0.0016666667 | D26: =((C26)*(H26)*(I26))/(G26*1) -> 0.10372583 | E26: =D26/10000 -> 1.0372583e-05 | G26: =digestion_page!B50 -> 0.4017 | H26: =digestion_page!C50 -> 25 | I26: =(LEFT(B26,FIND("/",B26)-1)/RIGHT(B26,LEN(B26)-FIND("/", B26))) -> 1
A28: cu_3 result: | C28: =AVERAGE(D25:D26) -> 0.11433168
A29: cu_3 result: | C29: =AVERAGE(E25:E26) -> 1.1433168e-05
A30: cu_3 lot:
A32: Ti_3 ICP analysis
A33: sample | B33: Dilution | C33: conc. [mg/L] | D33: Ti_3_ppm | E33: %Ti_3
A34: 200128354_1 | B34: ="1/1" -> 1/1 | C34: =AVERAGE(0.177,0.176,0.176,0.179) -> 0.177 | D34: =((C34)*(H34)*(I34))/(G34*1) -> 11.056972 | E34: =D34/10000 -> 0.0011056972 | G34: =digestion_page!B49 -> 0.4002 | H34: =digestion_page!C49 -> 25 | I34: =(LEFT(B34,FIND("/",B34)-1)/RIGHT(B34,LEN(B34)-FIND("/", B34))) -> 1
A35: 200128354_2 | B35: ="1/1" -> 1/1 | C35: =AVERAGE(0.035,0.033,0.035,0.036) -> 0.03475 | D35: =((C35)*(H35)*(I35))/(G35*1) -> 2.1626836 | E35: =D35/10000 -> 0.00021626836 | G35: =digestion_page!B50 -> 0.4017 | H35: =digestion_page!C50 -> 25 | I35: =(LEFT(B35,FIND("/",B35)-1)/RIGHT(B35,LEN(B35)-FIND("/", B35))) -> 1
A37: ti_3 result: | C37: =AVERAGE(D34:D35) -> 6.6098276
A38: ti_3 result: | C38: =AVERAGE(E34:E35) -> 0.00066098276
A39: ti_3 lot:
B41: Note(s):

Sheet formula_page
A1: ppm M+ = [conc.][volume][dilution]/[weight]
A3: %M+ = [conc.][volume][dilution]/([weight]*10,000)
A5: %MO = [oxide factor]*%M+
