Workbook

Sheet digestion_page
A1: Date: | B1: 46153
A2: Request ID: | B2: 100048502
A5: Microwave
A6: Element(s) | B6: Ca, Cr, Cu, Fe, K, Na, Ni, Zn
A7: SOP#
A8: Acid Cocktail | B8: 9 mL HCl, 3 mL HNO3, 3 mL H2SO4
A9: Rack | B9: 7
A10: Vessel | B10: PTFE
A11: Stir | B11: 0.9
A12: Time (min) | B12: Power (W) | C12: T1 (°C) | D12: T2 (°C) | E12: P (bar)
A13: 15 | B13: 1200 | C13: 180 | D13: 65 | E13: 110
A14: 15 | B14: 1500 | C14: 240 | D14: 65 | E14: 110
A15: 30 | B15: 1500 | C15: 240 | D15: 65 | E15: 110
A16: sample(s) | B16: weight (g) | C16: volume (mL)
A17: 200127815_1 | B17: 1.0045 | C17: 50
A18: 200127815_2 | B18: 1.0017 | C18: 50
A19: 200127815_3 | B19: 1.0118 | C19: 50
A20: 200127816_1 | B20: 1.5011 | C20: 50
A21: 200127816_2 | B21: 1.5053 | C21: 50
A22: 200127816_3 | B22: 1.5019 | C22: 50

Sheet 200127815
A1: Date: | B1: 46153
A2: Request ID: | B2: 100048502
A5: Ca ICP analysis
A6: sample | B6: Dilution | C6: conc. [mg/L] | D6: Ca_ppm | E6: %Ca
A7: 200127815_1 | B7: ="1/1" -> 1/1 | C7: 1.476 | D7: =((C7)*(H7)*(I7))/(G7*1) -> 73.469388 | E7: =D7/10000 -> 0.0073469388 | G7: =digestion_page!B17 -> 1.0045 | H7: =digestion_page!C17 -> 50 | I7: =(LEFT(B7,FIND("/",B7)-1)/RIGHT(B7,LEN(B7)-FIND("/", B7))) -> 1
A8: 200127815_2 | B8: ="1/1" -> 1/1 | C8: 1.474 | D8: =((C8)*(H8)*(I8))/(G8*1) -> 73.574923 | E8: =D8/10000 -> 0.0073574923 | G8: =digestion_page!B18 -> 1.0017 | H8: =digestion_page!C18 -> 50 | I8: =(LEFT(B8,FIND("/",B8)-1)/RIGHT(B8,LEN(B8)-FIND("/", B8))) -> 1
A9: 200127815_3 | B9: ="1/1" -> 1/1 | C9: 1.55 | D9: =((C9)*(H9)*(I9))/(G9*1) -> 76.596165 | E9: =D9/10000 -> 0.0076596165 | G9: =digestion_page!B19 -> 1.0118 | H9: =digestion_page!C19 -> 50 | I9: =(LEFT(B9,FIND("/",B9)-1)/RIGHT(B9,LEN(B9)-FIND("/", B9))) -> 1
A11: ca result: | C11: =AVERAGE(D7:D9) -> 74.546825
A12: ca result: | C12: =AVERAGE(E7:E9) -> 0.0074546825
A13: ca oxide factor:
A14: ca oxide result: | C14: =AVERAGE(E7:E9)*(C13) -> 0
A15: ca lot: | C15: Manufacturer: Assurance, 28-35CAY exp: 2026-10-30
A17: Cr ICP analysis
A18: sample | B18: Dilution | C18: conc. [mg/L] | D18: Cr_ppm | E18: %Cr
A19: 200127815_1 | B19: ="1/1" -> 1/1 | C19: 0.139 | D19: =((C19)*(H19)*(I19))/(G19*1) -> 6.9188651 | E19: =D19/10000 -> 0.00069188651 | G19: =digestion_page!B17 -> 1.0045 | H19: =digestion_page!C17 -> 50 | I19: =(LEFT(B19,FIND("/",B19)-1)/RIGHT(B19,LEN(B19)-FIND("/", B19))) -> 1
A20: 200127815_2 | B20: ="1/1" -> 1/1 | C20: 0.138 | D20: =((C20)*(H20)*(I20))/(G20*1) -> 6.8882899 | E20: =D20/10000 -> 0.00068882899 | G20: =digestion_page!B18 -> 1.0017 | H20: =digestion_page!C18 -> 50 | I20: =(LEFT(B20,FIND("/",B20)-1)/RIGHT(B20,LEN(B20)-FIND("/", B20))) -> 1
A21: 200127815_3 | B21: ="1/1" -> 1/1 | C21: 0.143 | D21: =((C21)*(H21)*(I21))/(G21*1) -> 7.066614 | E21: =D21/10000 -> 0.0007066614 | G21: =digestion_page!B19 -> 1.0118 | H21: =digestion_page!C19 -> 50 | I21: =(LEFT(B21,FIND("/",B21)-1)/RIGHT(B21,LEN(B21)-FIND("/", B21))) -> 1
A23: cr result: | C23: =AVERAGE(D19:D21) -> 6.957923
A24: cr result: | C24: =AVERAGE(E19:E21) -> 0.0006957923
A25: cr oxide factor:
A26: cr oxide result: | C26: =AVERAGE(E19:E21)*(C25) -> 0
A27: cr lot:
A29: Cu ICP analysis
A30: sample | B30: Dilution | C30: conc. [mg/L] | D30: Cu_ppm | E30: %Cu
A31: 200127815_1 | B31: ="1/1" -> 1/1 | C31: 0.731 | D31: =((C31)*(H31)*(I31))/(G31*1) -> 36.386262 | E31: =D31/10000 -> 0.0036386262 | G31: =digestion_page!B17 -> 1.0045 | H31: =digestion_page!C17 -> 50 | I31: =(LEFT(B31,FIND("/",B31)-1)/RIGHT(B31,LEN(B31)-FIND("/", B31))) -> 1
A32: 200127815_2 | B32: ="1/1" -> 1/1 | C32: 0.733 | D32: =((C32)*(H32)*(I32))/(G32*1) -> 36.587801 | E32: =D32/10000 -> 0.0036587801 | G32: =digestion_page!B18 -> 1.0017 | H32: =digestion_page!C18 -> 50 | I32: =(LEFT(B32,FIND("/",B32)-1)/RIGHT(B32,LEN(B32)-FIND("/", B32))) -> 1
A33: 200127815_3 | B33: ="1/1" -> 1/1 | D33: =((C33)*(H33)*(I33))/(G33*1) -> 0 | E33: =D33/10000 -> 0 | G33: =digestion_page!B19 -> 1.0118 | H33: =digestion_page!C19 -> 50 | I33: =(LEFT(B33,FIND("/",B33)-1)/RIGHT(B33,LEN(B33)-FIND("/", B33))) -> 1
A35: cu result: | C35: =AVERAGE(D31:D33) -> 24.324688
A36: cu result: | C36: =AVERAGE(E31:E33) -> 0.0024324688
A37: cu oxide factor:
A38: cu oxide result: | C38: =AVERAGE(E31:E33)*(C37) -> 0
A39: cu lot: | C39: Manufacturer: Assurance, 28-83CUT exp: 2026-09-30
A41: Fe ICP analysis
A42: sample | B42: Dilution | C42: conc. [mg/L] | D42: Fe_ppm | E42: %Fe
A43: 200127815_1 | B43: ="1/1" -> 1/1 | C43: 0.878 | D43: =((C43)*(H43)*(I43))/(G43*1) -> 43.703335 | E43: =D43/10000 -> 0.0043703335 | G43: =digestion_page!B17 -> 1.0045 | H43: =digestion_page!C17 -> 50 | I43: =(LEFT(B43,FIND("/",B43)-1)/RIGHT(B43,LEN(B43)-FIND("/", B43))) -> 1
A44: 200127815_2 | B44: ="1/1" -> 1/1 | C44: 0.819 | D44: =((C44)*(H44)*(I44))/(G44*1) -> 40.880503 | E44: =D44/10000 -> 0.0040880503 | G44: =digestion_page!B18 -> 1.0017 | H44: =digestion_page!C18 -> 50 | I44: =(LEFT(B44,FIND("/",B44)-1)/RIGHT(B44,LEN(B44)-FIND("/", B44))) -> 1
A45: 200127815_3 | B45: ="1/1" -> 1/1 | C45: 0.812 | D45: =((C45)*(H45)*(I45))/(G45*1) -> 40.126507 | E45: =D45/10000 -> 0.0040126507 | G45: =digestion_page!B19 -> 1.0118 | H45: =digestion_page!C19 -> 50 | I45: =(LEFT(B45,FIND("/",B45)-1)/RIGHT(B45,LEN(B45)-FIND("/", B45))) -> 1
A47: fe result: | C47: =AVERAGE(D43:D45) -> 41.570115
A48: fe result: | C48: =AVERAGE(E43:E45) -> 0.0041570115
A49: fe oxide factor:
...

Sheet 200127816
A1: Date: | B1: 46153
A2: Request ID: | B2: 100048502
A5: Ca ICP analysis
A6: sample | B6: Dilution | C6: conc. [mg/L] | D6: Ca_ppm | E6: %Ca
A7: 200127816_1 | B7: ="1/1" -> 1/1 | D7: =((C7)*(H7)*(I7))/(G7*1) -> 0 | E7: =D7/10000 -> 0 | G7: =digestion_page!B20 -> 1.5011 | H7: =digestion_page!C20 -> 50 | I7: =(LEFT(B7,FIND("/",B7)-1)/RIGHT(B7,LEN(B7)-FIND("/", B7))) -> 1
A8: 200127816_2 | B8: ="1/1" -> 1/1 | D8: =((C8)*(H8)*(I8))/(G8*1) -> 0 | E8: =D8/10000 -> 0 | G8: =digestion_page!B21 -> 1.5053 | H8: =digestion_page!C21 -> 50 | I8: =(LEFT(B8,FIND("/",B8)-1)/RIGHT(B8,LEN(B8)-FIND("/", B8))) -> 1
A9: 200127816_3 | B9: ="1/1" -> 1/1 | D9: =((C9)*(H9)*(I9))/(G9*1) -> 0 | E9: =D9/10000 -> 0 | G9: =digestion_page!B22 -> 1.5019 | H9: =digestion_page!C22 -> 50 | I9: =(LEFT(B9,FIND("/",B9)-1)/RIGHT(B9,LEN(B9)-FIND("/", B9))) -> 1
A11: ca result: | C11: =AVERAGE(D7:D9) -> 0
A12: ca result: | C12: =AVERAGE(E7:E9) -> 0
A13: ca oxide factor:
A14: ca oxide result: | C14: =AVERAGE(E7:E9)*(C13) -> 0
A15: ca lot: | C15: Manufacturer: Assurance, 28-35CAY exp: 2026-10-30
A17: Cr ICP analysis
A18: sample | B18: Dilution | C18: conc. [mg/L] | D18: Cr_ppm | E18: %Cr
A19: 200127816_1 | B19: ="1/1" -> 1/1 | D19: =((C19)*(H19)*(I19))/(G19*1) -> 0 | E19: =D19/10000 -> 0 | G19: =digestion_page!B20 -> 1.5011 | H19: =digestion_page!C20 -> 50 | I19: =(LEFT(B19,FIND("/",B19)-1)/RIGHT(B19,LEN(B19)-FIND("/", B19))) -> 1
A20: 200127816_2 | B20: ="1/1" -> 1/1 | D20: =((C20)*(H20)*(I20))/(G20*1) -> 0 | E20: =D20/10000 -> 0 | G20: =digestion_page!B21 -> 1.5053 | H20: =digestion_page!C21 -> 50 | I20: =(LEFT(B20,FIND("/",B20)-1)/RIGHT(B20,LEN(B20)-FIND("/", B20))) -> 1
A21: 200127816_3 | B21: ="1/1" -> 1/1 | D21: =((C21)*(H21)*(I21))/(G21*1) -> 0 | E21: =D21/10000 -> 0 | G21: =digestion_page!B22 -> 1.5019 | H21: =digestion_page!C22 -> 50 | I21: =(LEFT(B21,FIND("/",B21)-1)/RIGHT(B21,LEN(B21)-FIND("/", B21))) -> 1
A23: cr result: | C23: =AVERAGE(D19:D21) -> 0
A24: cr result: | C24: =AVERAGE(E19:E21) -> 0
A25: cr oxide factor:
A26: cr oxide result: | C26: =AVERAGE(E19:E21)*(C25) -> 0
A27: cr lot:
A29: Cu ICP analysis
A30: sample | B30: Dilution | C30: conc. [mg/L] | D30: Cu_ppm | E30: %Cu
A31: 200127816_1 | B31: ="1/1" -> 1/1 | D31: =((C31)*(H31)*(I31))/(G31*1) -> 0 | E31: =D31/10000 -> 0 | G31: =digestion_page!B20 -> 1.5011 | H31: =digestion_page!C20 -> 50 | I31: =(LEFT(B31,FIND("/",B31)-1)/RIGHT(B31,LEN(B31)-FIND("/", B31))) -> 1
A32: 200127816_2 | B32: ="1/1" -> 1/1 | D32: =((C32)*(H32)*(I32))/(G32*1) -> 0 | E32: =D32/10000 -> 0 | G32: =digestion_page!B21 -> 1.5053 | H32: =digestion_page!C21 -> 50 | I32: =(LEFT(B32,FIND("/",B32)-1)/RIGHT(B32,LEN(B32)-FIND("/", B32))) -> 1
A33: 200127816_3 | B33: ="1/1" -> 1/1 | D33: =((C33)*(H33)*(I33))/(G33*1) -> 0 | E33: =D33/10000 -> 0 | G33: =digestion_page!B22 -> 1.5019 | H33: =digestion_page!C22 -> 50 | I33: =(LEFT(B33,FIND("/",B33)-1)/RIGHT(B33,LEN(B33)-FIND("/", B33))) -> 1
A35: cu result: | C35: =AVERAGE(D31:D33) -> 0
A36: cu result: | C36: =AVERAGE(E31:E33) -> 0
A37: cu oxide factor:
A38: cu oxide result: | C38: =AVERAGE(E31:E33)*(C37) -> 0
A39: cu lot: | C39: Manufacturer: Assurance, 28-83CUT exp: 2026-09-30
A41: Fe ICP analysis
A42: sample | B42: Dilution | C42: conc. [mg/L] | D42: Fe_ppm | E42: %Fe
A43: 200127816_1 | B43: ="1/1" -> 1/1 | D43: =((C43)*(H43)*(I43))/(G43*1) -> 0 | E43: =D43/10000 -> 0 | G43: =digestion_page!B20 -> 1.5011 | H43: =digestion_page!C20 -> 50 | I43: =(LEFT(B43,FIND("/",B43)-1)/RIGHT(B43,LEN(B43)-FIND("/", B43))) -> 1
A44: 200127816_2 | B44: ="1/1" -> 1/1 | D44: =((C44)*(H44)*(I44))/(G44*1) -> 0 | E44: =D44/10000 -> 0 | G44: =digestion_page!B21 -> 1.5053 | H44: =digestion_page!C21 -> 50 | I44: =(LEFT(B44,FIND("/",B44)-1)/RIGHT(B44,LEN(B44)-FIND("/", B44))) -> 1
A45: 200127816_3 | B45: ="1/1" -> 1/1 | D45: =((C45)*(H45)*(I45))/(G45*1) -> 0 | E45: =D45/10000 -> 0 | G45: =digestion_page!B22 -> 1.5019 | H45: =digestion_page!C22 -> 50 | I45: =(LEFT(B45,FIND("/",B45)-1)/RIGHT(B45,LEN(B45)-FIND("/", B45))) -> 1
A47: fe result: | C47: =AVERAGE(D43:D45) -> 0
A48: fe result: | C48: =AVERAGE(E43:E45) -> 0
A49: fe oxide factor:
...

Sheet formula_page
A1: A = crucible
A2: B = crucible + sample
A3: C = crucible + sample after drying
A5: %LOI = ([B-A]-[C-A])/(B-A)*100%
A7: ppm M+ = [conc.][volume][dilution]/[weight]
A9: %M+ = [conc.][volume][dilution]/([weight]*10,000)
A11: %MO = [oxide factor]*%M+
A13: ppm M+ [dried] = ppm M+/([1-(%LOI)/100])
A15: %M+ [dried] = %M+/([1-(%LOI)/100])
A17: %MO [dried] = %MO/([1-(%LOI)/100])
A19: %Cr(VI) = (1.733[mL FAS][N FAS])/([weight])
A21: %Cr2O3 = 1.462*[%Cr(VI)]
A23: %Cr(III) = total_Cr - Cr(VI)
