Workbook

Sheet digestion_page
A1: Date: | B1: 46265
A2: Request ID: | B2: TEST
A5: Katanax
A6: Analyte(s) | B6: Ca, Cu
A7: SOP#
A8: Acid Cocktail
A9: sample(s) | B9: weight (g) | C9: volume (mL)
A10: 200120001_1 | C10: 250
A11: 200120001_2 | C11: 250
A12: 200120002_1 | C12: 250
A13: 200120002_2 | C13: 250
A16: Katanax
A17: Analyte(s) | B17: Cu, Al
A18: SOP#
A19: Acid Cocktail
A20: sample(s) | B20: weight (g) | C20: volume (mL)
A21: 200120002_3 | C21: 250
A22: 200120002_4 | C22: 250
A25: Katanax
A26: Analyte(s) | B26: Al
A27: SOP#
A28: Acid Cocktail
A29: sample(s) | B29: weight (g) | C29: volume (mL)
A30: 200120002_5 | C30: 250
A31: 200120002_6 | C31: 250
A34: Katanax
A35: Analyte(s) | B35: NH3
A36: SOP#
A37: Acid Cocktail
A38: sample(s) | B38: weight (g) | C38: volume (mL)
A39: 200120003_1 | C39: 250
A40: 200120003_2 | C40: 250
A43: Katanax
A44: Analyte(s) | B44: Cu
A45: SOP#
A46: Acid Cocktail
A47: sample(s) | B47: weight (g) | C47: volume (mL)
A48: 200120002_5 | C48: 250
A49: 200120002_6 | C49: 250

Sheet 200120001
A1: Date: | B1: 46265
A2: Request ID: | B2: TEST
A5: LOI temp:
A6: sample | B6: crucible (g) | C6: crucible + sample (g) | D6: ="after "&B5&" °C" -> 0 | E6: LOI (%) | F6: correction
A7: 200120001 | E7: =(((C7-B7)-(D7-B7))/(C7-B7))*100 -> 0 | F7: =1-(E7/100) -> 0
A9: Ca ICP analysis
A10: sample | B10: Dilution | C10: conc. [mg/L] | D10: Ca_ppm [dried] | E10: %Ca [dried]
A11: 200120001_1 | B11: ="1/1" -> 0 | D11: =((C11)*(H11)*(I11))/(G11*$F$7) -> 0 | E11: =D11/10000 -> 0 | G11: =digestion_page!B10 -> 0 | H11: =digestion_page!C10 -> 0 | I11: =(LEFT(B11,FIND("/",B11)-1)/RIGHT(B11,LEN(B11)-FIND("/", B11))) -> 0
A12: 200120001_2 | B12: ="1/1" -> 0 | D12: =((C12)*(H12)*(I12))/(G12*$F$7) -> 0 | E12: =D12/10000 -> 0 | G12: =digestion_page!B11 -> 0 | H12: =digestion_page!C11 -> 0 | I12: =(LEFT(B12,FIND("/",B12)-1)/RIGHT(B12,LEN(B12)-FIND("/", B12))) -> 0
A14: ca result: | C14: =AVERAGE(D11:D12) -> 0
A15: ca result: | C15: =AVERAGE(E11:E12) -> 0
A16: ca lot: | C16: Manufacturer: Assurance, 28-35CAY exp: 2026-10-30
A18: Cu ICP analysis
A19: sample | B19: Dilution | C19: conc. [mg/L] | D19: Cu_ppm [dried] | E19: %Cu [dried]
A20: 200120001_1 | B20: ="1/1" -> 0 | D20: =((C20)*(H20)*(I20))/(G20*$F$7) -> 0 | E20: =D20/10000 -> 0 | G20: =digestion_page!B10 -> 0 | H20: =digestion_page!C10 -> 0 | I20: =(LEFT(B20,FIND("/",B20)-1)/RIGHT(B20,LEN(B20)-FIND("/", B20))) -> 0
A21: 200120001_2 | B21: ="1/1" -> 0 | D21: =((C21)*(H21)*(I21))/(G21*$F$7) -> 0 | E21: =D21/10000 -> 0 | G21: =digestion_page!B11 -> 0 | H21: =digestion_page!C11 -> 0 | I21: =(LEFT(B21,FIND("/",B21)-1)/RIGHT(B21,LEN(B21)-FIND("/", B21))) -> 0
A23: cu result: | C23: =AVERAGE(D20:D21) -> 0
A24: cu result: | C24: =AVERAGE(E20:E21) -> 0
A25: cu lot: | C25: Manufacturer: Assurance, 28-83CUT exp: 2026-09-30
B27: Note(s):

Sheet 200120002
A1: Date: | B1: 46265
A2: Request ID: | B2: TEST
A5: LOI temp:
A6: sample | B6: crucible (g) | C6: crucible + sample (g) | D6: ="after "&B5&" °C" -> 0 | E6: LOI (%) | F6: correction
A7: 200120002 | E7: =(((C7-B7)-(D7-B7))/(C7-B7))*100 -> 0 | F7: =1-(E7/100) -> 0
A9: Al ICP analysis
A10: sample | B10: Dilution | C10: conc. [mg/L] | D10: Al_ppm [dried] | E10: %Al [dried]
A11: 200120002_3 | B11: ="1/1" -> 0 | D11: =((C11)*(H11)*(I11))/(G11*$F$7) -> 0 | E11: =D11/10000 -> 0 | G11: =digestion_page!B21 -> 0 | H11: =digestion_page!C21 -> 0 | I11: =(LEFT(B11,FIND("/",B11)-1)/RIGHT(B11,LEN(B11)-FIND("/", B11))) -> 0
A12: 200120002_4 | B12: ="1/1" -> 0 | D12: =((C12)*(H12)*(I12))/(G12*$F$7) -> 0 | E12: =D12/10000 -> 0 | G12: =digestion_page!B22 -> 0 | H12: =digestion_page!C22 -> 0 | I12: =(LEFT(B12,FIND("/",B12)-1)/RIGHT(B12,LEN(B12)-FIND("/", B12))) -> 0
A14: al result: | C14: =AVERAGE(D11:D12) -> 0
A15: al result: | C15: =AVERAGE(E11:E12) -> 0
A16: al lot:
A18: Al ICP analysis
A19: sample | B19: Dilution | C19: conc. [mg/L] | D19: Al_ppm [dried] | E19: %Al [dried]
A20: 200120002_5 | B20: ="1/1" -> 0 | D20: =((C20)*(H20)*(I20))/(G20*$F$7) -> 0 | E20: =D20/10000 -> 0 | G20: =digestion_page!B30 -> 0 | H20: =digestion_page!C30 -> 0 | I20: =(LEFT(B20,FIND("/",B20)-1)/RIGHT(B20,LEN(B20)-FIND("/", B20))) -> 0
A21: 200120002_6 | B21: ="1/1" -> 0 | D21: =((C21)*(H21)*(I21))/(G21*$F$7) -> 0 | E21: =D21/10000 -> 0 | G21: =digestion_page!B31 -> 0 | H21: =digestion_page!C31 -> 0 | I21: =(LEFT(B21,FIND("/",B21)-1)/RIGHT(B21,LEN(B21)-FIND("/", B21))) -> 0
A23: al result: | C23: =AVERAGE(D20:D21) -> 0
A24: al result: | C24: =AVERAGE(E20:E21) -> 0
A25: al lot:
A27: Ca ICP analysis
A28: sample | B28: Dilution | C28: conc. [mg/L] | D28: Ca_ppm [dried] | E28: %Ca [dried]
A29: 200120002_1 | B29: ="1/1" -> 0 | D29: =((C29)*(H29)*(I29))/(G29*$F$7) -> 0 | E29: =D29/10000 -> 0 | G29: =digestion_page!B12 -> 0 | H29: =digestion_page!C12 -> 0 | I29: =(LEFT(B29,FIND("/",B29)-1)/RIGHT(B29,LEN(B29)-FIND("/", B29))) -> 0
A30: 200120002_2 | B30: ="1/1" -> 0 | D30: =((C30)*(H30)*(I30))/(G30*$F$7) -> 0 | E30: =D30/10000 -> 0 | G30: =digestion_page!B13 -> 0 | H30: =digestion_page!C13 -> 0 | I30: =(LEFT(B30,FIND("/",B30)-1)/RIGHT(B30,LEN(B30)-FIND("/", B30))) -> 0
A32: ca result: | C32: =AVERAGE(D29:D30) -> 0
A33: ca result: | C33: =AVERAGE(E29:E30) -> 0
A34: ca lot: | C34: Manufacturer: Assurance, 28-35CAY exp: 2026-10-30
A36: Cu ICP analysis
A37: sample | B37: Dilution | C37: conc. [mg/L] | D37: Cu_ppm [dried] | E37: %Cu [dried]
A38: 200120002_1 | B38: ="1/1" -> 0 | D38: =((C38)*(H38)*(I38))/(G38*$F$7) -> 0 | E38: =D38/10000 -> 0 | G38: =digestion_page!B12 -> 0 | H38: =digestion_page!C12 -> 0 | I38: =(LEFT(B38,FIND("/",B38)-1)/RIGHT(B38,LEN(B38)-FIND("/", B38))) -> 0
A39: 200120002_2 | B39: ="1/1" -> 0 | D39: =((C39)*(H39)*(I39))/(G39*$F$7) -> 0 | E39: =D39/10000 -> 0 | G39: =digestion_page!B13 -> 0 | H39: =digestion_page!C13 -> 0 | I39: =(LEFT(B39,FIND("/",B39)-1)/RIGHT(B39,LEN(B39)-FIND("/", B39))) -> 0
A41: cu result: | C41: =AVERAGE(D38:D39) -> 0
A42: cu result: | C42: =AVERAGE(E38:E39) -> 0
A43: cu lot: | C43: Manufacturer: Assurance, 28-83CUT exp: 2026-09-30
A45: Cu ICP analysis
A46: sample | B46: Dilution | C46: conc. [mg/L] | D46: Cu_ppm [dried] | E46: %Cu [dried]
A47: 200120002_3 | B47: ="1/1" -> 0 | D47: =((C47)*(H47)*(I47))/(G47*$F$7) -> 0 | E47: =D47/10000 -> 0 | G47: =digestion_page!B21 -> 0 | H47: =digestion_page!C21 -> 0 | I47: =(LEFT(B47,FIND("/",B47)-1)/RIGHT(B47,LEN(B47)-FIND("/", B47))) -> 0
A48: 200120002_4 | B48: ="1/1" -> 0 | D48: =((C48)*(H48)*(I48))/(G48*$F$7) -> 0 | E48: =D48/10000 -> 0 | G48: =digestion_page!B22 -> 0 | H48: =digestion_page!C22 -> 0 | I48: =(LEFT(B48,FIND("/",B48)-1)/RIGHT(B48,LEN(B48)-FIND("/", B48))) -> 0
A50: cu result: | C50: =AVERAGE(D47:D48) -> 0
A51: cu result: | C51: =AVERAGE(E47:E48) -> 0
A52: cu lot: | C52: Manufacturer: Assurance, 28-83CUT exp: 2026-09-30
...

Sheet 200120003
A1: Date: | B1: 46265
A2: Request ID: | B2: TEST
A5: LOI temp:
A6: sample | B6: crucible (g) | C6: crucible + sample (g) | D6: ="after "&B5&" °C" -> 0 | E6: LOI (%) | F6: correction
A7: 200120003 | E7: =(((C7-B7)-(D7-B7))/(C7-B7))*100 -> 0 | F7: =1-(E7/100) -> 0
A9: NH3 ISE analysis
A10: sample | B10: Dilution | C10: conc. [mg/L] | D10: NH3_ppm [dried] | E10: %NH3 [dried]
A11: 200120003_1 | B11: ="1/1" -> 0 | D11: =((C11)*(H11)*(I11))/(G11*$F$7) -> 0 | E11: =D11/10000 -> 0 | G11: =digestion_page!B39 -> 0 | H11: =digestion_page!C39 -> 0 | I11: =(LEFT(B11,FIND("/",B11)-1)/RIGHT(B11,LEN(B11)-FIND("/", B11))) -> 0
A12: 200120003_2 | B12: ="1/1" -> 0 | D12: =((C12)*(H12)*(I12))/(G12*$F$7) -> 0 | E12: =D12/10000 -> 0 | G12: =digestion_page!B40 -> 0 | H12: =digestion_page!C40 -> 0 | I12: =(LEFT(B12,FIND("/",B12)-1)/RIGHT(B12,LEN(B12)-FIND("/", B12))) -> 0
A14: nh3 result: | C14: =AVERAGE(D11:D12) -> 0
A15: nh3 result: | C15: =AVERAGE(E11:E12) -> 0
A16: nh3 lot:
B18: Note(s):

Sheet formula_page
A1: ppm M+ = [conc.][volume][dilution]/[weight]
A3: %M+ = [conc.][volume][dilution]/([weight]*10,000)
A5: A = crucible
A6: B = crucible + sample
A7: C = crucible + sample after drying
A9: %LOI = ([B-A]-[C-A])/(B-A)*100%
A11: ppm M+ [dried] = ppm M+/([1-(%LOI)/100])
A13: %M+ [dried] = %M+/([1-(%LOI)/100])
